package com.github.backtolifemod.backtolife.world;

import java.util.Random;

import net.minecraft.entity.IEntityLivingData;
import net.minecraft.entity.passive.EntityVillager;
import net.minecraft.init.Blocks;
import net.minecraft.util.EnumFacing;
import net.minecraft.util.math.BlockPos;
import net.minecraft.world.World;

import com.github.backtolifemod.backtolife.core.ModBlocks;
import com.github.backtolifemod.backtolife.core.ModWorld;

public class StructureScientistHouse {

	public static boolean generate(World world, Random rand, int x, int y, int z, EnumFacing facing) {
		if (facing == EnumFacing.SOUTH) {
			generateNorth(world, rand, x - 5, y - 5, z - 5);
		}

		if (facing == EnumFacing.EAST) {
			generateWest(world, rand, x - 5, y - 5, z - 5);
		}

		if (facing == EnumFacing.WEST) {
			generateEast(world, rand, x - 5, y - 5, z - 5);
		}

		if (facing == EnumFacing.NORTH) {
			generateSouth(world, rand, x - 5, y - 5, z - 5);
		}
		return true;
	}

	public static boolean generateSouth(World world, Random rand, int x, int y, int z) {
		StructureUtils.setBlock(world, x + 2, y + 0, z + 0, ModBlocks.laboratory_block, 0, 3);
		StructureUtils.setBlock(world, x + 3, y + 0, z + 0, ModBlocks.laboratory_block, 0, 3);
		StructureUtils.setBlock(world, x + 4, y + 0, z + 0, ModBlocks.laboratory_block, 0, 3);
		StructureUtils.setBlock(world, x + 5, y + 0, z + 0, ModBlocks.laboratory_block, 0, 3);
		StructureUtils.setBlock(world, x + 6, y + 0, z + 0, ModBlocks.laboratory_block, 0, 3);
		StructureUtils.setBlock(world, x + 2, y + 0, z + 1, ModBlocks.laboratory_block, 0, 3);
		StructureUtils.setBlock(world, x + 3, y + 0, z + 1, Blocks.GRASS_PATH, 0, 3);
		StructureUtils.setBlock(world, x + 4, y + 0, z + 1, Blocks.GRASS_PATH, 0, 3);
		StructureUtils.setBlock(world, x + 5, y + 0, z + 1, Blocks.GRASS_PATH, 0, 3);
		StructureUtils.setBlock(world, x + 6, y + 0, z + 1, ModBlocks.laboratory_block, 0, 3);
		StructureUtils.setBlock(world, x + 2, y + 0, z + 2, ModBlocks.laboratory_block, 0, 3);
		StructureUtils.setBlock(world, x + 3, y + 0, z + 2, Blocks.GRASS_PATH, 0, 3);
		StructureUtils.setBlock(world, x + 4, y + 0, z + 2, Blocks.GRASS_PATH, 0, 3);
		StructureUtils.setBlock(world, x + 5, y + 0, z + 2, Blocks.GRASS_PATH, 0, 3);
		StructureUtils.setBlock(world, x + 6, y + 0, z + 2, ModBlocks.laboratory_block, 0, 3);
		StructureUtils.setBlock(world, x + 2, y + 0, z + 3, ModBlocks.laboratory_block, 0, 3);
		StructureUtils.setBlock(world, x + 3, y + 0, z + 3, Blocks.GRASS_PATH, 0, 3);
		StructureUtils.setBlock(world, x + 4, y + 0, z + 3, Blocks.GRASS_PATH, 0, 3);
		StructureUtils.setBlock(world, x + 5, y + 0, z + 3, Blocks.GRASS_PATH, 0, 3);
		StructureUtils.setBlock(world, x + 6, y + 0, z + 3, ModBlocks.laboratory_block, 0, 3);
		StructureUtils.setBlock(world, x + 0, y + 0, z + 4, ModBlocks.laboratory_block, 0, 3);
		StructureUtils.setBlock(world, x + 1, y + 0, z + 4, ModBlocks.laboratory_block, 0, 3);
		StructureUtils.setBlock(world, x + 2, y + 0, z + 4, ModBlocks.laboratory_block, 0, 3);
		StructureUtils.setBlock(world, x + 3, y + 0, z + 4, ModBlocks.laboratory_block, 0, 3);
		StructureUtils.setBlock(world, x + 4, y + 0, z + 4, ModBlocks.laboratory_block, 0, 3);
		StructureUtils.setBlock(world, x + 5, y + 0, z + 4, ModBlocks.laboratory_block, 0, 3);
		StructureUtils.setBlock(world, x + 6, y + 0, z + 4, ModBlocks.laboratory_block, 0, 3);
		StructureUtils.setBlock(world, x + 7, y + 0, z + 4, ModBlocks.laboratory_block, 0, 3);
		StructureUtils.setBlock(world, x + 8, y + 0, z + 4, ModBlocks.laboratory_block, 0, 3);
		StructureUtils.setBlock(world, x + 0, y + 0, z + 5, ModBlocks.laboratory_block, 0, 3);
		StructureUtils.setBlock(world, x + 1, y + 0, z + 5, ModBlocks.laboratory_block, 0, 3);
		StructureUtils.setBlock(world, x + 2, y + 0, z + 5, ModBlocks.laboratory_block, 0, 3);
		StructureUtils.setBlock(world, x + 3, y + 0, z + 5, ModBlocks.laboratory_block, 0, 3);
		StructureUtils.setBlock(world, x + 4, y + 0, z + 5, ModBlocks.laboratory_block, 0, 3);
		StructureUtils.setBlock(world, x + 5, y + 0, z + 5, ModBlocks.laboratory_block, 0, 3);
		StructureUtils.setBlock(world, x + 6, y + 0, z + 5, ModBlocks.laboratory_block, 0, 3);
		StructureUtils.setBlock(world, x + 7, y + 0, z + 5, ModBlocks.laboratory_block, 0, 3);
		StructureUtils.setBlock(world, x + 8, y + 0, z + 5, ModBlocks.laboratory_block, 0, 3);
		StructureUtils.setBlock(world, x + 0, y + 0, z + 6, ModBlocks.laboratory_block, 0, 3);
		StructureUtils.setBlock(world, x + 1, y + 0, z + 6, ModBlocks.laboratory_block, 0, 3);
		StructureUtils.setBlock(world, x + 2, y + 0, z + 6, ModBlocks.laboratory_block, 0, 3);
		StructureUtils.setBlock(world, x + 3, y + 0, z + 6, ModBlocks.laboratory_block, 0, 3);
		StructureUtils.setBlock(world, x + 4, y + 0, z + 6, ModBlocks.laboratory_block, 0, 3);
		StructureUtils.setBlock(world, x + 5, y + 0, z + 6, ModBlocks.laboratory_block, 0, 3);
		StructureUtils.setBlock(world, x + 6, y + 0, z + 6, ModBlocks.laboratory_block, 0, 3);
		StructureUtils.setBlock(world, x + 7, y + 0, z + 6, ModBlocks.laboratory_block, 0, 3);
		StructureUtils.setBlock(world, x + 8, y + 0, z + 6, ModBlocks.laboratory_block, 0, 3);
		StructureUtils.setBlock(world, x + 0, y + 0, z + 7, ModBlocks.laboratory_block, 0, 3);
		StructureUtils.setBlock(world, x + 1, y + 0, z + 7, ModBlocks.laboratory_block, 0, 3);
		StructureUtils.setBlock(world, x + 2, y + 0, z + 7, ModBlocks.laboratory_light_panel, 0, 3);
		StructureUtils.setBlock(world, x + 3, y + 0, z + 7, ModBlocks.laboratory_block, 0, 3);
		StructureUtils.setBlock(world, x + 4, y + 0, z + 7, ModBlocks.laboratory_block, 0, 3);
		StructureUtils.setBlock(world, x + 5, y + 0, z + 7, ModBlocks.laboratory_block, 0, 3);
		StructureUtils.setBlock(world, x + 6, y + 0, z + 7, ModBlocks.laboratory_light_panel, 0, 3);
		StructureUtils.setBlock(world, x + 7, y + 0, z + 7, ModBlocks.laboratory_block, 0, 3);
		StructureUtils.setBlock(world, x + 8, y + 0, z + 7, ModBlocks.laboratory_block, 0, 3);
		StructureUtils.setBlock(world, x + 0, y + 0, z + 8, ModBlocks.laboratory_block, 0, 3);
		StructureUtils.setBlock(world, x + 1, y + 0, z + 8, ModBlocks.laboratory_block, 0, 3);
		StructureUtils.setBlock(world, x + 2, y + 0, z + 8, ModBlocks.laboratory_block, 0, 3);
		StructureUtils.setBlock(world, x + 3, y + 0, z + 8, ModBlocks.laboratory_block, 0, 3);
		StructureUtils.setBlock(world, x + 4, y + 0, z + 8, ModBlocks.laboratory_block, 0, 3);
		StructureUtils.setBlock(world, x + 5, y + 0, z + 8, ModBlocks.laboratory_block, 0, 3);
		StructureUtils.setBlock(world, x + 6, y + 0, z + 8, ModBlocks.laboratory_block, 0, 3);
		StructureUtils.setBlock(world, x + 7, y + 0, z + 8, ModBlocks.laboratory_block, 0, 3);
		StructureUtils.setBlock(world, x + 8, y + 0, z + 8, ModBlocks.laboratory_block, 0, 3);
		StructureUtils.setBlock(world, x + 0, y + 0, z + 9, ModBlocks.laboratory_block, 0, 3);
		StructureUtils.setBlock(world, x + 1, y + 0, z + 9, ModBlocks.laboratory_block, 0, 3);
		StructureUtils.setBlock(world, x + 2, y + 0, z + 9, ModBlocks.laboratory_block, 0, 3);
		StructureUtils.setBlock(world, x + 3, y + 0, z + 9, ModBlocks.laboratory_block, 0, 3);
		StructureUtils.setBlock(world, x + 4, y + 0, z + 9, ModBlocks.laboratory_block, 0, 3);
		StructureUtils.setBlock(world, x + 5, y + 0, z + 9, ModBlocks.laboratory_block, 0, 3);
		StructureUtils.setBlock(world, x + 6, y + 0, z + 9, ModBlocks.laboratory_block, 0, 3);
		StructureUtils.setBlock(world, x + 7, y + 0, z + 9, ModBlocks.laboratory_block, 0, 3);
		StructureUtils.setBlock(world, x + 8, y + 0, z + 9, ModBlocks.laboratory_block, 0, 3);
		StructureUtils.setBlock(world, x + 2, y + 1, z + 0, ModBlocks.laboratory_block, 0, 3);
		StructureUtils.setBlock(world, x + 3, y + 1, z + 0, ModBlocks.laboratory_block, 0, 3);
		StructureUtils.setBlock(world, x + 4, y + 1, z + 0, ModBlocks.laboratory_block, 0, 3);
		StructureUtils.setBlock(world, x + 5, y + 1, z + 0, ModBlocks.laboratory_block, 0, 3);
		StructureUtils.setBlock(world, x + 6, y + 1, z + 0, ModBlocks.laboratory_block, 0, 3);
		StructureUtils.setBlock(world, x + 2, y + 1, z + 1, ModBlocks.laboratory_block, 0, 3);
		StructureUtils.setBlock(world, x + 3, y + 1, z + 1, Blocks.AIR, 0, 3);
		StructureUtils.setBlock(world, x + 4, y + 1, z + 1, Blocks.AIR, 0, 3);
		StructureUtils.setBlock(world, x + 5, y + 1, z + 1, Blocks.AIR, 0, 3);
		StructureUtils.setBlock(world, x + 6, y + 1, z + 1, ModBlocks.laboratory_block, 0, 3);
		StructureUtils.setBlock(world, x + 2, y + 1, z + 2, ModBlocks.laboratory_block, 0, 3);
		StructureUtils.setBlock(world, x + 3, y + 1, z + 2, Blocks.AIR, 0, 3);
		StructureUtils.setBlock(world, x + 4, y + 1, z + 2, Blocks.AIR, 0, 3);
		StructureUtils.setBlock(world, x + 5, y + 1, z + 2, Blocks.AIR, 0, 3);
		StructureUtils.setBlock(world, x + 6, y + 1, z + 2, ModBlocks.laboratory_block, 0, 3);
		StructureUtils.setBlock(world, x + 2, y + 1, z + 3, ModBlocks.laboratory_block, 0, 3);
		StructureUtils.setBlock(world, x + 3, y + 1, z + 3, Blocks.AIR, 0, 3);
		StructureUtils.setBlock(world, x + 4, y + 1, z + 3, Blocks.AIR, 0, 3);
		StructureUtils.setBlock(world, x + 5, y + 1, z + 3, Blocks.AIR, 0, 3);
		StructureUtils.setBlock(world, x + 6, y + 1, z + 3, ModBlocks.laboratory_block, 0, 3);
		StructureUtils.setBlock(world, x + 0, y + 1, z + 4, ModBlocks.laboratory_block, 0, 3);
		StructureUtils.setBlock(world, x + 1, y + 1, z + 4, ModBlocks.laboratory_block, 0, 3);
		StructureUtils.setBlock(world, x + 2, y + 1, z + 4, ModBlocks.laboratory_block, 0, 3);
		StructureUtils.setBlock(world, x + 3, y + 1, z + 4, Blocks.GLASS, 0, 3);
		StructureUtils.setBlock(world, x + 4, y + 1, z + 4, Blocks.GLASS, 0, 3);
		StructureUtils.setBlock(world, x + 5, y + 1, z + 4, Blocks.GLASS, 0, 3);
		StructureUtils.setBlock(world, x + 6, y + 1, z + 4, ModBlocks.laboratory_block, 0, 3);
		StructureUtils.setBlock(world, x + 7, y + 1, z + 4, ModBlocks.laboratory_block, 0, 3);
		StructureUtils.setBlock(world, x + 8, y + 1, z + 4, ModBlocks.laboratory_block, 0, 3);
		StructureUtils.setBlock(world, x + 0, y + 1, z + 5, ModBlocks.laboratory_block, 0, 3);
		StructureUtils.setBlock(world, x + 1, y + 1, z + 5, Blocks.CHEST, 5, 3);
		StructureUtils.setBlock(world, x + 2, y + 1, z + 5, Blocks.AIR, 0, 3);
		StructureUtils.setBlock(world, x + 3, y + 1, z + 5, Blocks.AIR, 0, 3);
		StructureUtils.setBlock(world, x + 4, y + 1, z + 5, Blocks.AIR, 0, 3);
		StructureUtils.setBlock(world, x + 5, y + 1, z + 5, Blocks.AIR, 0, 3);
		StructureUtils.setBlock(world, x + 6, y + 1, z + 5, Blocks.AIR, 0, 3);
		StructureUtils.setBlock(world, x + 7, y + 1, z + 5, Blocks.AIR, 0, 3);
		StructureUtils.setBlock(world, x + 8, y + 1, z + 5, ModBlocks.laboratory_block, 0, 3);
		StructureUtils.setBlock(world, x + 0, y + 1, z + 6, ModBlocks.laboratory_block, 0, 3);
		StructureUtils.setBlock(world, x + 1, y + 1, z + 6, Blocks.AIR, 0, 3);
		StructureUtils.setBlock(world, x + 2, y + 1, z + 6, Blocks.AIR, 0, 3);
		StructureUtils.setBlock(world, x + 3, y + 1, z + 6, Blocks.AIR, 0, 3);
		StructureUtils.setBlock(world, x + 4, y + 1, z + 6, Blocks.AIR, 0, 3);
		StructureUtils.setBlock(world, x + 5, y + 1, z + 6, Blocks.AIR, 0, 3);
		StructureUtils.setBlock(world, x + 6, y + 1, z + 6, Blocks.AIR, 0, 3);
		StructureUtils.setBlock(world, x + 7, y + 1, z + 6, ModBlocks.fossil_slicer, 1, 3);
		StructureUtils.setBlock(world, x + 8, y + 1, z + 6, ModBlocks.laboratory_block, 0, 3);
		StructureUtils.setBlock(world, x + 0, y + 1, z + 7, ModBlocks.laboratory_block, 0, 3);
		StructureUtils.setBlock(world, x + 1, y + 1, z + 7, Blocks.CHEST, 5, 3);
		StructureUtils.setBlock(world, x + 2, y + 1, z + 7, Blocks.AIR, 0, 3);
		StructureUtils.setBlock(world, x + 3, y + 1, z + 7, Blocks.AIR, 0, 3);
		StructureUtils.setBlock(world, x + 4, y + 1, z + 7, Blocks.AIR, 0, 3);
		StructureUtils.setBlock(world, x + 5, y + 1, z + 7, Blocks.AIR, 0, 3);
		StructureUtils.setBlock(world, x + 6, y + 1, z + 7, Blocks.AIR, 0, 3);
		StructureUtils.setBlock(world, x + 7, y + 1, z + 7, Blocks.AIR, 0, 3);
		StructureUtils.setBlock(world, x + 8, y + 1, z + 7, ModBlocks.laboratory_block, 0, 3);
		StructureUtils.setBlock(world, x + 0, y + 1, z + 8, ModBlocks.laboratory_block, 0, 3);
		StructureUtils.setBlock(world, x + 1, y + 1, z + 8, Blocks.CHEST, 5, 3);
		StructureUtils.setBlock(world, x + 2, y + 1, z + 8, Blocks.AIR, 0, 3);
		StructureUtils.setBlock(world, x + 3, y + 1, z + 8, ModBlocks.fertilization_machine, 2, 3);
		StructureUtils.setBlock(world, x + 4, y + 1, z + 8, Blocks.AIR, 0, 3);
		StructureUtils.setBlock(world, x + 5, y + 1, z + 8, ModBlocks.tissue_analyzer, 2, 3);
		StructureUtils.setBlock(world, x + 6, y + 1, z + 8, Blocks.AIR, 0, 3);
		StructureUtils.setBlock(world, x + 8, y + 1, z + 8, ModBlocks.laboratory_block, 0, 3);
		StructureUtils.setBlock(world, x + 0, y + 1, z + 9, ModBlocks.laboratory_block, 0, 3);
		StructureUtils.setBlock(world, x + 1, y + 1, z + 9, ModBlocks.laboratory_block, 0, 3);
		StructureUtils.setBlock(world, x + 2, y + 1, z + 9, ModBlocks.laboratory_block, 0, 3);
		StructureUtils.setBlock(world, x + 3, y + 1, z + 9, ModBlocks.laboratory_block, 0, 3);
		StructureUtils.setBlock(world, x + 4, y + 1, z + 9, ModBlocks.laboratory_block, 0, 3);
		StructureUtils.setBlock(world, x + 5, y + 1, z + 9, ModBlocks.laboratory_block, 0, 3);
		StructureUtils.setBlock(world, x + 6, y + 1, z + 9, ModBlocks.laboratory_block, 0, 3);
		StructureUtils.setBlock(world, x + 7, y + 1, z + 9, ModBlocks.laboratory_block, 0, 3);
		StructureUtils.setBlock(world, x + 8, y + 1, z + 9, ModBlocks.laboratory_block, 0, 3);
		StructureUtils.setBlock(world, x + 2, y + 2, z + 0, ModBlocks.laboratory_block, 0, 3);
		StructureUtils.setBlock(world, x + 3, y + 2, z + 0, ModBlocks.laboratory_block, 0, 3);
		StructureUtils.setBlock(world, x + 4, y + 2, z + 0, ModBlocks.laboratory_light_panel, 0, 3);
		StructureUtils.setBlock(world, x + 5, y + 2, z + 0, ModBlocks.laboratory_block, 0, 3);
		StructureUtils.setBlock(world, x + 6, y + 2, z + 0, ModBlocks.laboratory_block, 0, 3);
		StructureUtils.setBlock(world, x + 2, y + 2, z + 1, ModBlocks.laboratory_block, 0, 3);
		StructureUtils.setBlock(world, x + 3, y + 2, z + 1, Blocks.AIR, 0, 3);
		StructureUtils.setBlock(world, x + 4, y + 2, z + 1, Blocks.AIR, 0, 3);
		StructureUtils.setBlock(world, x + 5, y + 2, z + 1, Blocks.AIR, 0, 3);
		StructureUtils.setBlock(world, x + 6, y + 2, z + 1, ModBlocks.laboratory_block, 0, 3);
		StructureUtils.setBlock(world, x + 2, y + 2, z + 2, ModBlocks.laboratory_light_panel, 0, 3);
		StructureUtils.setBlock(world, x + 3, y + 2, z + 2, Blocks.AIR, 0, 3);
		StructureUtils.setBlock(world, x + 4, y + 2, z + 2, Blocks.AIR, 0, 3);
		StructureUtils.setBlock(world, x + 5, y + 2, z + 2, Blocks.AIR, 0, 3);
		StructureUtils.setBlock(world, x + 6, y + 2, z + 2, ModBlocks.laboratory_light_panel, 0, 3);
		StructureUtils.setBlock(world, x + 2, y + 2, z + 3, ModBlocks.laboratory_block, 0, 3);
		StructureUtils.setBlock(world, x + 3, y + 2, z + 3, Blocks.AIR, 0, 3);
		StructureUtils.setBlock(world, x + 4, y + 2, z + 3, Blocks.AIR, 0, 3);
		StructureUtils.setBlock(world, x + 5, y + 2, z + 3, Blocks.AIR, 0, 3);
		StructureUtils.setBlock(world, x + 6, y + 2, z + 3, ModBlocks.laboratory_block, 0, 3);
		StructureUtils.setBlock(world, x + 0, y + 2, z + 4, ModBlocks.laboratory_block, 0, 3);
		StructureUtils.setBlock(world, x + 1, y + 2, z + 4, ModBlocks.laboratory_block, 0, 3);
		StructureUtils.setBlock(world, x + 2, y + 2, z + 4, ModBlocks.laboratory_block, 0, 3);
		StructureUtils.setBlock(world, x + 3, y + 2, z + 4, Blocks.GLASS, 0, 3);
		StructureUtils.setBlock(world, x + 4, y + 2, z + 4, Blocks.GLASS, 0, 3);
		StructureUtils.setBlock(world, x + 5, y + 2, z + 4, Blocks.GLASS, 0, 3);
		StructureUtils.setBlock(world, x + 6, y + 2, z + 4, ModBlocks.laboratory_block, 0, 3);
		StructureUtils.setBlock(world, x + 7, y + 2, z + 4, ModBlocks.laboratory_block, 0, 3);
		StructureUtils.setBlock(world, x + 8, y + 2, z + 4, ModBlocks.laboratory_block, 0, 3);
		StructureUtils.setBlock(world, x + 0, y + 2, z + 5, ModBlocks.laboratory_block, 0, 3);
		StructureUtils.setBlock(world, x + 1, y + 2, z + 5, Blocks.AIR, 0, 3);
		StructureUtils.setBlock(world, x + 2, y + 2, z + 5, Blocks.AIR, 0, 3);
		StructureUtils.setBlock(world, x + 3, y + 2, z + 5, Blocks.AIR, 0, 3);
		StructureUtils.setBlock(world, x + 4, y + 2, z + 5, Blocks.AIR, 0, 3);
		StructureUtils.setBlock(world, x + 5, y + 2, z + 5, Blocks.AIR, 0, 3);
		StructureUtils.setBlock(world, x + 6, y + 2, z + 5, Blocks.AIR, 0, 3);
		StructureUtils.setBlock(world, x + 7, y + 2, z + 5, Blocks.AIR, 0, 3);
		StructureUtils.setBlock(world, x + 8, y + 2, z + 5, ModBlocks.laboratory_block, 0, 3);
		StructureUtils.setBlock(world, x + 0, y + 2, z + 6, ModBlocks.laboratory_block, 0, 3);
		StructureUtils.setBlock(world, x + 1, y + 2, z + 6, Blocks.AIR, 0, 3);
		StructureUtils.setBlock(world, x + 2, y + 2, z + 6, Blocks.AIR, 0, 3);
		StructureUtils.setBlock(world, x + 3, y + 2, z + 6, Blocks.AIR, 0, 3);
		StructureUtils.setBlock(world, x + 4, y + 2, z + 6, Blocks.AIR, 0, 3);
		StructureUtils.setBlock(world, x + 5, y + 2, z + 6, Blocks.AIR, 0, 3);
		StructureUtils.setBlock(world, x + 6, y + 2, z + 6, Blocks.AIR, 0, 3);
		StructureUtils.setBlock(world, x + 7, y + 2, z + 6, Blocks.AIR, 0, 3);
		StructureUtils.setBlock(world, x + 8, y + 2, z + 6, ModBlocks.laboratory_block, 0, 3);
		StructureUtils.setBlock(world, x + 0, y + 2, z + 7, ModBlocks.laboratory_block, 0, 3);
		StructureUtils.setBlock(world, x + 1, y + 2, z + 7, Blocks.AIR, 0, 3);
		StructureUtils.setBlock(world, x + 2, y + 2, z + 7, Blocks.AIR, 0, 3);
		StructureUtils.setBlock(world, x + 3, y + 2, z + 7, Blocks.AIR, 0, 3);
		StructureUtils.setBlock(world, x + 4, y + 2, z + 7, Blocks.AIR, 0, 3);
		StructureUtils.setBlock(world, x + 5, y + 2, z + 7, Blocks.AIR, 0, 3);
		StructureUtils.setBlock(world, x + 6, y + 2, z + 7, Blocks.AIR, 0, 3);
		StructureUtils.setBlock(world, x + 7, y + 2, z + 7, Blocks.AIR, 0, 3);
		StructureUtils.setBlock(world, x + 8, y + 2, z + 7, ModBlocks.laboratory_block, 0, 3);
		StructureUtils.setBlock(world, x + 0, y + 2, z + 8, ModBlocks.laboratory_block, 0, 3);
		StructureUtils.setBlock(world, x + 1, y + 2, z + 8, Blocks.AIR, 0, 3);
		StructureUtils.setBlock(world, x + 2, y + 2, z + 8, Blocks.AIR, 0, 3);
		StructureUtils.setBlock(world, x + 3, y + 2, z + 8, Blocks.AIR, 0, 3);
		StructureUtils.setBlock(world, x + 4, y + 2, z + 8, Blocks.AIR, 0, 3);
		StructureUtils.setBlock(world, x + 5, y + 2, z + 8, Blocks.AIR, 0, 3);
		StructureUtils.setBlock(world, x + 6, y + 2, z + 8, Blocks.AIR, 0, 3);
		StructureUtils.setBlock(world, x + 8, y + 2, z + 8, ModBlocks.laboratory_block, 0, 3);
		StructureUtils.setBlock(world, x + 0, y + 2, z + 9, ModBlocks.laboratory_block, 0, 3);
		StructureUtils.setBlock(world, x + 1, y + 2, z + 9, ModBlocks.laboratory_block, 0, 3);
		StructureUtils.setBlock(world, x + 2, y + 2, z + 9, ModBlocks.laboratory_block, 0, 3);
		StructureUtils.setBlock(world, x + 3, y + 2, z + 9, ModBlocks.laboratory_block, 0, 3);
		StructureUtils.setBlock(world, x + 4, y + 2, z + 9, ModBlocks.laboratory_block, 0, 3);
		StructureUtils.setBlock(world, x + 5, y + 2, z + 9, ModBlocks.laboratory_block, 0, 3);
		StructureUtils.setBlock(world, x + 6, y + 2, z + 9, ModBlocks.laboratory_block, 0, 3);
		StructureUtils.setBlock(world, x + 7, y + 2, z + 9, ModBlocks.laboratory_block, 0, 3);
		StructureUtils.setBlock(world, x + 8, y + 2, z + 9, ModBlocks.laboratory_block, 0, 3);
		StructureUtils.setBlock(world, x + 2, y + 3, z + 0, ModBlocks.laboratory_block, 0, 3);
		StructureUtils.setBlock(world, x + 3, y + 3, z + 0, ModBlocks.laboratory_block, 0, 3);
		StructureUtils.setBlock(world, x + 4, y + 3, z + 0, ModBlocks.laboratory_block, 0, 3);
		StructureUtils.setBlock(world, x + 5, y + 3, z + 0, ModBlocks.laboratory_block, 0, 3);
		StructureUtils.setBlock(world, x + 6, y + 3, z + 0, ModBlocks.laboratory_block, 0, 3);
		StructureUtils.setBlock(world, x + 2, y + 3, z + 1, ModBlocks.laboratory_block, 0, 3);
		StructureUtils.setBlock(world, x + 3, y + 3, z + 1, Blocks.AIR, 0, 3);
		StructureUtils.setBlock(world, x + 4, y + 3, z + 1, Blocks.AIR, 0, 3);
		StructureUtils.setBlock(world, x + 5, y + 3, z + 1, Blocks.AIR, 0, 3);
		StructureUtils.setBlock(world, x + 6, y + 3, z + 1, ModBlocks.laboratory_block, 0, 3);
		StructureUtils.setBlock(world, x + 2, y + 3, z + 2, ModBlocks.laboratory_block, 0, 3);
		StructureUtils.setBlock(world, x + 3, y + 3, z + 2, Blocks.AIR, 0, 3);
		StructureUtils.setBlock(world, x + 4, y + 3, z + 2, Blocks.AIR, 0, 3);
		StructureUtils.setBlock(world, x + 5, y + 3, z + 2, Blocks.AIR, 0, 3);
		StructureUtils.setBlock(world, x + 6, y + 3, z + 2, ModBlocks.laboratory_block, 0, 3);
		StructureUtils.setBlock(world, x + 2, y + 3, z + 3, ModBlocks.laboratory_block, 0, 3);
		StructureUtils.setBlock(world, x + 3, y + 3, z + 3, Blocks.AIR, 0, 3);
		StructureUtils.setBlock(world, x + 4, y + 3, z + 3, Blocks.AIR, 0, 3);
		StructureUtils.setBlock(world, x + 5, y + 3, z + 3, Blocks.AIR, 0, 3);
		StructureUtils.setBlock(world, x + 6, y + 3, z + 3, ModBlocks.laboratory_block, 0, 3);
		StructureUtils.setBlock(world, x + 0, y + 3, z + 4, ModBlocks.laboratory_block, 0, 3);
		StructureUtils.setBlock(world, x + 1, y + 3, z + 4, ModBlocks.laboratory_block, 0, 3);
		StructureUtils.setBlock(world, x + 2, y + 3, z + 4, ModBlocks.laboratory_block, 0, 3);
		StructureUtils.setBlock(world, x + 3, y + 3, z + 4, Blocks.GLASS, 0, 3);
		StructureUtils.setBlock(world, x + 4, y + 3, z + 4, Blocks.GLASS, 0, 3);
		StructureUtils.setBlock(world, x + 5, y + 3, z + 4, Blocks.GLASS, 0, 3);
		StructureUtils.setBlock(world, x + 6, y + 3, z + 4, ModBlocks.laboratory_block, 0, 3);
		StructureUtils.setBlock(world, x + 7, y + 3, z + 4, ModBlocks.laboratory_block, 0, 3);
		StructureUtils.setBlock(world, x + 8, y + 3, z + 4, ModBlocks.laboratory_block, 0, 3);
		StructureUtils.setBlock(world, x + 0, y + 3, z + 5, ModBlocks.laboratory_block, 0, 3);
		StructureUtils.setBlock(world, x + 1, y + 3, z + 5, Blocks.AIR, 0, 3);
		StructureUtils.setBlock(world, x + 2, y + 3, z + 5, Blocks.AIR, 0, 3);
		StructureUtils.setBlock(world, x + 3, y + 3, z + 5, Blocks.AIR, 0, 3);
		StructureUtils.setBlock(world, x + 4, y + 3, z + 5, Blocks.AIR, 0, 3);
		StructureUtils.setBlock(world, x + 5, y + 3, z + 5, Blocks.AIR, 0, 3);
		StructureUtils.setBlock(world, x + 6, y + 3, z + 5, Blocks.AIR, 0, 3);
		StructureUtils.setBlock(world, x + 7, y + 3, z + 5, Blocks.AIR, 0, 3);
		StructureUtils.setBlock(world, x + 8, y + 3, z + 5, ModBlocks.laboratory_block, 0, 3);
		StructureUtils.setBlock(world, x + 0, y + 3, z + 6, ModBlocks.laboratory_block, 0, 3);
		StructureUtils.setBlock(world, x + 1, y + 3, z + 6, Blocks.AIR, 0, 3);
		StructureUtils.setBlock(world, x + 2, y + 3, z + 6, Blocks.AIR, 0, 3);
		StructureUtils.setBlock(world, x + 3, y + 3, z + 6, Blocks.AIR, 0, 3);
		StructureUtils.setBlock(world, x + 4, y + 3, z + 6, Blocks.AIR, 0, 3);
		StructureUtils.setBlock(world, x + 5, y + 3, z + 6, Blocks.AIR, 0, 3);
		StructureUtils.setBlock(world, x + 6, y + 3, z + 6, Blocks.AIR, 0, 3);
		StructureUtils.setBlock(world, x + 7, y + 3, z + 6, Blocks.AIR, 0, 3);
		StructureUtils.setBlock(world, x + 8, y + 3, z + 6, ModBlocks.laboratory_block, 0, 3);
		StructureUtils.setBlock(world, x + 0, y + 3, z + 7, ModBlocks.laboratory_block, 0, 3);
		StructureUtils.setBlock(world, x + 1, y + 3, z + 7, Blocks.AIR, 0, 3);
		StructureUtils.setBlock(world, x + 2, y + 3, z + 7, Blocks.AIR, 0, 3);
		StructureUtils.setBlock(world, x + 3, y + 3, z + 7, Blocks.AIR, 0, 3);
		StructureUtils.setBlock(world, x + 4, y + 3, z + 7, Blocks.AIR, 0, 3);
		StructureUtils.setBlock(world, x + 5, y + 3, z + 7, Blocks.AIR, 0, 3);
		StructureUtils.setBlock(world, x + 6, y + 3, z + 7, Blocks.AIR, 0, 3);
		StructureUtils.setBlock(world, x + 7, y + 3, z + 7, Blocks.AIR, 0, 3);
		StructureUtils.setBlock(world, x + 8, y + 3, z + 7, ModBlocks.laboratory_block, 0, 3);
		StructureUtils.setBlock(world, x + 0, y + 3, z + 8, ModBlocks.laboratory_block, 0, 3);
		StructureUtils.setBlock(world, x + 1, y + 3, z + 8, Blocks.AIR, 0, 3);
		StructureUtils.setBlock(world, x + 2, y + 3, z + 8, Blocks.AIR, 0, 3);
		StructureUtils.setBlock(world, x + 3, y + 3, z + 8, Blocks.AIR, 0, 3);
		StructureUtils.setBlock(world, x + 4, y + 3, z + 8, Blocks.AIR, 0, 3);
		StructureUtils.setBlock(world, x + 5, y + 3, z + 8, Blocks.AIR, 0, 3);
		StructureUtils.setBlock(world, x + 6, y + 3, z + 8, Blocks.AIR, 0, 3);
		StructureUtils.setBlock(world, x + 8, y + 3, z + 8, ModBlocks.laboratory_block, 0, 3);
		StructureUtils.setBlock(world, x + 0, y + 3, z + 9, ModBlocks.laboratory_block, 0, 3);
		StructureUtils.setBlock(world, x + 1, y + 3, z + 9, ModBlocks.laboratory_block, 0, 3);
		StructureUtils.setBlock(world, x + 2, y + 3, z + 9, ModBlocks.laboratory_block, 0, 3);
		StructureUtils.setBlock(world, x + 3, y + 3, z + 9, ModBlocks.laboratory_block, 0, 3);
		StructureUtils.setBlock(world, x + 4, y + 3, z + 9, ModBlocks.laboratory_block, 0, 3);
		StructureUtils.setBlock(world, x + 5, y + 3, z + 9, ModBlocks.laboratory_block, 0, 3);
		StructureUtils.setBlock(world, x + 6, y + 3, z + 9, ModBlocks.laboratory_block, 0, 3);
		StructureUtils.setBlock(world, x + 7, y + 3, z + 9, ModBlocks.laboratory_block, 0, 3);
		StructureUtils.setBlock(world, x + 8, y + 3, z + 9, ModBlocks.laboratory_block, 0, 3);
		StructureUtils.setBlock(world, x + 2, y + 4, z + 0, ModBlocks.laboratory_block, 0, 3);
		StructureUtils.setBlock(world, x + 3, y + 4, z + 0, ModBlocks.laboratory_block, 0, 3);
		StructureUtils.setBlock(world, x + 4, y + 4, z + 0, ModBlocks.laboratory_block, 0, 3);
		StructureUtils.setBlock(world, x + 5, y + 4, z + 0, ModBlocks.laboratory_block, 0, 3);
		StructureUtils.setBlock(world, x + 6, y + 4, z + 0, ModBlocks.laboratory_block, 0, 3);
		StructureUtils.setBlock(world, x + 2, y + 4, z + 1, ModBlocks.laboratory_block, 0, 3);
		StructureUtils.setBlock(world, x + 3, y + 4, z + 1, ModBlocks.laboratory_block, 0, 3);
		StructureUtils.setBlock(world, x + 4, y + 4, z + 1, ModBlocks.laboratory_block, 0, 3);
		StructureUtils.setBlock(world, x + 5, y + 4, z + 1, ModBlocks.laboratory_block, 0, 3);
		StructureUtils.setBlock(world, x + 6, y + 4, z + 1, ModBlocks.laboratory_block, 0, 3);
		StructureUtils.setBlock(world, x + 2, y + 4, z + 2, ModBlocks.laboratory_block, 0, 3);
		StructureUtils.setBlock(world, x + 3, y + 4, z + 2, ModBlocks.laboratory_block, 0, 3);
		StructureUtils.setBlock(world, x + 4, y + 4, z + 2, ModBlocks.laboratory_block, 0, 3);
		StructureUtils.setBlock(world, x + 5, y + 4, z + 2, ModBlocks.laboratory_block, 0, 3);
		StructureUtils.setBlock(world, x + 6, y + 4, z + 2, ModBlocks.laboratory_block, 0, 3);
		StructureUtils.setBlock(world, x + 2, y + 4, z + 3, ModBlocks.laboratory_block, 0, 3);
		StructureUtils.setBlock(world, x + 3, y + 4, z + 3, ModBlocks.laboratory_block, 0, 3);
		StructureUtils.setBlock(world, x + 4, y + 4, z + 3, ModBlocks.laboratory_block, 0, 3);
		StructureUtils.setBlock(world, x + 5, y + 4, z + 3, ModBlocks.laboratory_block, 0, 3);
		StructureUtils.setBlock(world, x + 6, y + 4, z + 3, ModBlocks.laboratory_block, 0, 3);
		StructureUtils.setBlock(world, x + 0, y + 4, z + 4, ModBlocks.laboratory_block, 0, 3);
		StructureUtils.setBlock(world, x + 1, y + 4, z + 4, ModBlocks.laboratory_block, 0, 3);
		StructureUtils.setBlock(world, x + 2, y + 4, z + 4, ModBlocks.laboratory_block, 0, 3);
		StructureUtils.setBlock(world, x + 3, y + 4, z + 4, ModBlocks.laboratory_block, 0, 3);
		StructureUtils.setBlock(world, x + 4, y + 4, z + 4, ModBlocks.laboratory_block, 0, 3);
		StructureUtils.setBlock(world, x + 5, y + 4, z + 4, ModBlocks.laboratory_block, 0, 3);
		StructureUtils.setBlock(world, x + 6, y + 4, z + 4, ModBlocks.laboratory_block, 0, 3);
		StructureUtils.setBlock(world, x + 7, y + 4, z + 4, ModBlocks.laboratory_block, 0, 3);
		StructureUtils.setBlock(world, x + 8, y + 4, z + 4, ModBlocks.laboratory_block, 0, 3);
		StructureUtils.setBlock(world, x + 0, y + 4, z + 5, ModBlocks.laboratory_block, 0, 3);
		StructureUtils.setBlock(world, x + 1, y + 4, z + 5, ModBlocks.laboratory_block, 0, 3);
		StructureUtils.setBlock(world, x + 2, y + 4, z + 5, ModBlocks.laboratory_block, 0, 3);
		StructureUtils.setBlock(world, x + 3, y + 4, z + 5, ModBlocks.laboratory_block, 0, 3);
		StructureUtils.setBlock(world, x + 4, y + 4, z + 5, ModBlocks.laboratory_block, 0, 3);
		StructureUtils.setBlock(world, x + 5, y + 4, z + 5, ModBlocks.laboratory_block, 0, 3);
		StructureUtils.setBlock(world, x + 6, y + 4, z + 5, ModBlocks.laboratory_block, 0, 3);
		StructureUtils.setBlock(world, x + 7, y + 4, z + 5, ModBlocks.laboratory_block, 0, 3);
		StructureUtils.setBlock(world, x + 8, y + 4, z + 5, ModBlocks.laboratory_block, 0, 3);
		StructureUtils.setBlock(world, x + 0, y + 4, z + 6, ModBlocks.laboratory_block, 0, 3);
		StructureUtils.setBlock(world, x + 1, y + 4, z + 6, ModBlocks.laboratory_block, 0, 3);
		StructureUtils.setBlock(world, x + 2, y + 4, z + 6, ModBlocks.laboratory_block, 0, 3);
		StructureUtils.setBlock(world, x + 3, y + 4, z + 6, ModBlocks.laboratory_block, 0, 3);
		StructureUtils.setBlock(world, x + 4, y + 4, z + 6, ModBlocks.laboratory_block, 0, 3);
		StructureUtils.setBlock(world, x + 5, y + 4, z + 6, ModBlocks.laboratory_block, 0, 3);
		StructureUtils.setBlock(world, x + 6, y + 4, z + 6, ModBlocks.laboratory_block, 0, 3);
		StructureUtils.setBlock(world, x + 7, y + 4, z + 6, ModBlocks.laboratory_block, 0, 3);
		StructureUtils.setBlock(world, x + 8, y + 4, z + 6, ModBlocks.laboratory_block, 0, 3);
		StructureUtils.setBlock(world, x + 0, y + 4, z + 7, ModBlocks.laboratory_block, 0, 3);
		StructureUtils.setBlock(world, x + 1, y + 4, z + 7, ModBlocks.laboratory_block, 0, 3);
		StructureUtils.setBlock(world, x + 2, y + 4, z + 7, ModBlocks.laboratory_light_panel, 0, 3);
		StructureUtils.setBlock(world, x + 3, y + 4, z + 7, ModBlocks.laboratory_block, 0, 3);
		StructureUtils.setBlock(world, x + 4, y + 4, z + 7, ModBlocks.laboratory_block, 0, 3);
		StructureUtils.setBlock(world, x + 5, y + 4, z + 7, ModBlocks.laboratory_block, 0, 3);
		StructureUtils.setBlock(world, x + 6, y + 4, z + 7, ModBlocks.laboratory_light_panel, 0, 3);
		StructureUtils.setBlock(world, x + 7, y + 4, z + 7, ModBlocks.laboratory_block, 0, 3);
		StructureUtils.setBlock(world, x + 8, y + 4, z + 7, ModBlocks.laboratory_block, 0, 3);
		StructureUtils.setBlock(world, x + 0, y + 4, z + 8, ModBlocks.laboratory_block, 0, 3);
		StructureUtils.setBlock(world, x + 1, y + 4, z + 8, ModBlocks.laboratory_block, 0, 3);
		StructureUtils.setBlock(world, x + 2, y + 4, z + 8, ModBlocks.laboratory_block, 0, 3);
		StructureUtils.setBlock(world, x + 3, y + 4, z + 8, ModBlocks.laboratory_block, 0, 3);
		StructureUtils.setBlock(world, x + 4, y + 4, z + 8, ModBlocks.laboratory_block, 0, 3);
		StructureUtils.setBlock(world, x + 5, y + 4, z + 8, ModBlocks.laboratory_block, 0, 3);
		StructureUtils.setBlock(world, x + 6, y + 4, z + 8, ModBlocks.laboratory_block, 0, 3);
		StructureUtils.setBlock(world, x + 8, y + 4, z + 8, ModBlocks.laboratory_block, 0, 3);
		StructureUtils.setBlock(world, x + 0, y + 4, z + 9, ModBlocks.laboratory_block, 0, 3);
		StructureUtils.setBlock(world, x + 1, y + 4, z + 9, ModBlocks.laboratory_block, 0, 3);
		StructureUtils.setBlock(world, x + 2, y + 4, z + 9, ModBlocks.laboratory_block, 0, 3);
		StructureUtils.setBlock(world, x + 3, y + 4, z + 9, ModBlocks.laboratory_block, 0, 3);
		StructureUtils.setBlock(world, x + 4, y + 4, z + 9, ModBlocks.laboratory_block, 0, 3);
		StructureUtils.setBlock(world, x + 5, y + 4, z + 9, ModBlocks.laboratory_block, 0, 3);
		StructureUtils.setBlock(world, x + 6, y + 4, z + 9, ModBlocks.laboratory_block, 0, 3);
		StructureUtils.setBlock(world, x + 7, y + 4, z + 9, ModBlocks.laboratory_block, 0, 3);
		StructureUtils.setBlock(world, x + 8, y + 4, z + 9, ModBlocks.laboratory_block, 0, 3);
		StructureUtils.setBlock(world, x + 7, y + 5, z + 6, ModBlocks.laboratory_block, 0, 3);
		StructureUtils.setBlock(world, x + 6, y + 5, z + 7, ModBlocks.laboratory_block, 0, 3);
		StructureUtils.setBlock(world, x + 8, y + 5, z + 7, ModBlocks.laboratory_block, 0, 3);
		StructureUtils.setBlock(world, x + 6, y + 5, z + 8, ModBlocks.laboratory_block, 0, 3);
		StructureUtils.setBlock(world, x + 8, y + 5, z + 8, ModBlocks.laboratory_block, 0, 3);
		StructureUtils.setBlock(world, x + 7, y + 5, z + 9, ModBlocks.laboratory_block, 0, 3);
		StructureUtils.setBlock(world, x + 2, y + 6, z + 0, Blocks.GRASS, 0, 3);
		StructureUtils.setBlock(world, x + 3, y + 6, z + 0, Blocks.GRASS, 0, 3);
		StructureUtils.setBlock(world, x + 4, y + 6, z + 0, Blocks.GRASS, 0, 3);
		StructureUtils.setBlock(world, x + 5, y + 6, z + 0, Blocks.GRASS, 0, 3);
		StructureUtils.setBlock(world, x + 6, y + 6, z + 0, Blocks.GRASS, 0, 3);
		StructureUtils.setBlock(world, x + 7, y + 6, z + 0, Blocks.GRASS, 0, 3);
		StructureUtils.setBlock(world, x + 8, y + 6, z + 0, Blocks.GRASS, 0, 3);
		StructureUtils.setBlock(world, x + 2, y + 6, z + 1, Blocks.GRASS, 0, 3);
		StructureUtils.setBlock(world, x + 3, y + 6, z + 1, Blocks.GRASS, 0, 3);
		StructureUtils.setBlock(world, x + 4, y + 6, z + 1, Blocks.GRASS, 0, 3);
		StructureUtils.setBlock(world, x + 5, y + 6, z + 1, Blocks.GRASS, 0, 3);
		StructureUtils.setBlock(world, x + 6, y + 6, z + 1, Blocks.GRASS, 0, 3);
		StructureUtils.setBlock(world, x + 7, y + 6, z + 1, Blocks.GRASS, 0, 3);
		StructureUtils.setBlock(world, x + 8, y + 6, z + 1, Blocks.GRASS, 0, 3);
		StructureUtils.setBlock(world, x + 2, y + 6, z + 2, Blocks.GRASS, 0, 3);
		StructureUtils.setBlock(world, x + 3, y + 6, z + 2, Blocks.GRASS, 0, 3);
		StructureUtils.setBlock(world, x + 4, y + 6, z + 2, Blocks.GRASS, 0, 3);
		StructureUtils.setBlock(world, x + 5, y + 6, z + 2, Blocks.GRASS, 0, 3);
		StructureUtils.setBlock(world, x + 6, y + 6, z + 2, Blocks.GRASS, 0, 3);
		StructureUtils.setBlock(world, x + 7, y + 6, z + 2, Blocks.GRASS, 0, 3);
		StructureUtils.setBlock(world, x + 8, y + 6, z + 2, Blocks.GRASS, 0, 3);
		StructureUtils.setBlock(world, x + 2, y + 6, z + 3, Blocks.GRASS, 0, 3);
		StructureUtils.setBlock(world, x + 3, y + 6, z + 3, Blocks.GRASS, 0, 3);
		StructureUtils.setBlock(world, x + 4, y + 6, z + 3, Blocks.GRASS, 0, 3);
		StructureUtils.setBlock(world, x + 5, y + 6, z + 3, Blocks.GRASS, 0, 3);
		StructureUtils.setBlock(world, x + 6, y + 6, z + 3, Blocks.COBBLESTONE, 0, 3);
		StructureUtils.setBlock(world, x + 7, y + 6, z + 3, Blocks.GRASS, 0, 3);
		StructureUtils.setBlock(world, x + 8, y + 6, z + 3, Blocks.GRASS, 0, 3);
		StructureUtils.setBlock(world, x + 0, y + 6, z + 4, Blocks.COBBLESTONE, 0, 3);
		StructureUtils.setBlock(world, x + 1, y + 6, z + 4, Blocks.COBBLESTONE, 0, 3);
		StructureUtils.setBlock(world, x + 2, y + 6, z + 4, Blocks.COBBLESTONE, 0, 3);
		StructureUtils.setBlock(world, x + 3, y + 6, z + 4, Blocks.COBBLESTONE, 0, 3);
		StructureUtils.setBlock(world, x + 4, y + 6, z + 4, Blocks.COBBLESTONE, 0, 3);
		StructureUtils.setBlock(world, x + 5, y + 6, z + 4, Blocks.COBBLESTONE, 0, 3);
		StructureUtils.setBlock(world, x + 6, y + 6, z + 4, Blocks.COBBLESTONE, 0, 3);
		StructureUtils.setBlock(world, x + 7, y + 6, z + 4, Blocks.COBBLESTONE, 0, 3);
		StructureUtils.setBlock(world, x + 8, y + 6, z + 4, Blocks.COBBLESTONE, 0, 3);
		StructureUtils.setBlock(world, x + 0, y + 6, z + 5, Blocks.COBBLESTONE, 0, 3);
		StructureUtils.setBlock(world, x + 1, y + 6, z + 5, Blocks.PLANKS, 0, 3);
		StructureUtils.setBlock(world, x + 2, y + 6, z + 5, Blocks.PLANKS, 0, 3);
		StructureUtils.setBlock(world, x + 3, y + 6, z + 5, Blocks.PLANKS, 0, 3);
		StructureUtils.setBlock(world, x + 4, y + 6, z + 5, Blocks.PLANKS, 0, 3);
		StructureUtils.setBlock(world, x + 5, y + 6, z + 5, Blocks.PLANKS, 0, 3);
		StructureUtils.setBlock(world, x + 6, y + 6, z + 5, Blocks.PLANKS, 0, 3);
		StructureUtils.setBlock(world, x + 7, y + 6, z + 5, Blocks.PLANKS, 0, 3);
		StructureUtils.setBlock(world, x + 8, y + 6, z + 5, Blocks.COBBLESTONE, 0, 3);
		StructureUtils.setBlock(world, x + 0, y + 6, z + 6, Blocks.COBBLESTONE, 0, 3);
		StructureUtils.setBlock(world, x + 1, y + 6, z + 6, Blocks.PLANKS, 0, 3);
		StructureUtils.setBlock(world, x + 2, y + 6, z + 6, Blocks.PLANKS, 0, 3);
		StructureUtils.setBlock(world, x + 3, y + 6, z + 6, Blocks.PLANKS, 0, 3);
		StructureUtils.setBlock(world, x + 4, y + 6, z + 6, Blocks.PLANKS, 0, 3);
		StructureUtils.setBlock(world, x + 5, y + 6, z + 6, Blocks.DOUBLE_STONE_SLAB, 0, 3);
		StructureUtils.setBlock(world, x + 6, y + 6, z + 6, Blocks.DOUBLE_STONE_SLAB, 0, 3);
		StructureUtils.setBlock(world, x + 7, y + 6, z + 6, Blocks.DOUBLE_STONE_SLAB, 0, 3);
		StructureUtils.setBlock(world, x + 8, y + 6, z + 6, Blocks.COBBLESTONE, 0, 3);
		StructureUtils.setBlock(world, x + 0, y + 6, z + 7, Blocks.COBBLESTONE, 0, 3);
		StructureUtils.setBlock(world, x + 1, y + 6, z + 7, Blocks.PLANKS, 0, 3);
		StructureUtils.setBlock(world, x + 2, y + 6, z + 7, Blocks.PLANKS, 0, 3);
		StructureUtils.setBlock(world, x + 3, y + 6, z + 7, Blocks.PLANKS, 0, 3);
		StructureUtils.setBlock(world, x + 4, y + 6, z + 7, Blocks.PLANKS, 0, 3);
		StructureUtils.setBlock(world, x + 5, y + 6, z + 7, Blocks.DOUBLE_STONE_SLAB, 0, 3);
		StructureUtils.setBlock(world, x + 6, y + 6, z + 7, Blocks.DOUBLE_STONE_SLAB, 0, 3);
		StructureUtils.setBlock(world, x + 7, y + 6, z + 7, Blocks.DOUBLE_STONE_SLAB, 0, 3);
		StructureUtils.setBlock(world, x + 8, y + 6, z + 7, Blocks.COBBLESTONE, 0, 3);
		StructureUtils.setBlock(world, x + 0, y + 6, z + 8, Blocks.COBBLESTONE, 0, 3);
		StructureUtils.setBlock(world, x + 1, y + 6, z + 8, Blocks.PLANKS, 0, 3);
		StructureUtils.setBlock(world, x + 2, y + 6, z + 8, Blocks.PLANKS, 0, 3);
		StructureUtils.setBlock(world, x + 3, y + 6, z + 8, Blocks.PLANKS, 0, 3);
		StructureUtils.setBlock(world, x + 4, y + 6, z + 8, Blocks.PLANKS, 0, 3);
		StructureUtils.setBlock(world, x + 5, y + 6, z + 8, Blocks.DOUBLE_STONE_SLAB, 0, 3);
		StructureUtils.setBlock(world, x + 6, y + 6, z + 8, Blocks.DOUBLE_STONE_SLAB, 0, 3);
		StructureUtils.setBlock(world, x + 7, y + 6, z + 8, Blocks.IRON_TRAPDOOR, 0, 3);
		StructureUtils.setBlock(world, x + 8, y + 6, z + 8, Blocks.COBBLESTONE, 0, 3);
		StructureUtils.setBlock(world, x + 0, y + 6, z + 9, Blocks.COBBLESTONE, 0, 3);
		StructureUtils.setBlock(world, x + 1, y + 6, z + 9, Blocks.COBBLESTONE, 0, 3);
		StructureUtils.setBlock(world, x + 2, y + 6, z + 9, Blocks.COBBLESTONE, 0, 3);
		StructureUtils.setBlock(world, x + 3, y + 6, z + 9, Blocks.COBBLESTONE, 0, 3);
		StructureUtils.setBlock(world, x + 4, y + 6, z + 9, Blocks.COBBLESTONE, 0, 3);
		StructureUtils.setBlock(world, x + 5, y + 6, z + 9, Blocks.COBBLESTONE, 0, 3);
		StructureUtils.setBlock(world, x + 6, y + 6, z + 9, Blocks.COBBLESTONE, 0, 3);
		StructureUtils.setBlock(world, x + 7, y + 6, z + 9, Blocks.COBBLESTONE, 0, 3);
		StructureUtils.setBlock(world, x + 8, y + 6, z + 9, Blocks.COBBLESTONE, 0, 3);
		StructureUtils.setBlock(world, x + 2, y + 6, z + 10, Blocks.STONE_STAIRS, 3, 3);
		StructureUtils.setBlock(world, x + 2, y + 7, z + 0, Blocks.OAK_FENCE, 0, 3);
		StructureUtils.setBlock(world, x + 3, y + 7, z + 0, Blocks.OAK_FENCE, 0, 3);
		StructureUtils.setBlock(world, x + 4, y + 7, z + 0, Blocks.OAK_FENCE, 0, 3);
		StructureUtils.setBlock(world, x + 5, y + 7, z + 0, Blocks.OAK_FENCE, 0, 3);
		StructureUtils.setBlock(world, x + 6, y + 7, z + 0, Blocks.OAK_FENCE, 0, 3);
		StructureUtils.setBlock(world, x + 7, y + 7, z + 0, Blocks.OAK_FENCE, 0, 3);
		StructureUtils.setBlock(world, x + 8, y + 7, z + 0, Blocks.OAK_FENCE, 0, 3);
		StructureUtils.setBlock(world, x + 2, y + 7, z + 1, Blocks.OAK_FENCE, 0, 3);
		StructureUtils.setBlock(world, x + 3, y + 7, z + 1, Blocks.AIR, 0, 3);
		StructureUtils.setBlock(world, x + 4, y + 7, z + 1, Blocks.AIR, 0, 3);
		StructureUtils.setBlock(world, x + 5, y + 7, z + 1, Blocks.AIR, 0, 3);
		StructureUtils.setBlock(world, x + 6, y + 7, z + 1, Blocks.AIR, 0, 3);
		StructureUtils.setBlock(world, x + 7, y + 7, z + 1, Blocks.AIR, 0, 3);
		StructureUtils.setBlock(world, x + 8, y + 7, z + 1, Blocks.OAK_FENCE, 0, 3);
		StructureUtils.setBlock(world, x + 2, y + 7, z + 2, Blocks.OAK_FENCE, 0, 3);
		StructureUtils.setBlock(world, x + 3, y + 7, z + 2, Blocks.AIR, 0, 3);
		StructureUtils.setBlock(world, x + 4, y + 7, z + 2, Blocks.AIR, 0, 3);
		StructureUtils.setBlock(world, x + 5, y + 7, z + 2, Blocks.AIR, 0, 3);
		StructureUtils.setBlock(world, x + 6, y + 7, z + 2, Blocks.AIR, 0, 3);
		StructureUtils.setBlock(world, x + 7, y + 7, z + 2, Blocks.AIR, 0, 3);
		StructureUtils.setBlock(world, x + 8, y + 7, z + 2, Blocks.OAK_FENCE, 0, 3);
		StructureUtils.setBlock(world, x + 2, y + 7, z + 3, Blocks.OAK_FENCE, 0, 3);
		StructureUtils.setBlock(world, x + 3, y + 7, z + 3, Blocks.AIR, 0, 3);
		StructureUtils.setBlock(world, x + 4, y + 7, z + 3, Blocks.AIR, 0, 3);
		StructureUtils.setBlock(world, x + 5, y + 7, z + 3, Blocks.AIR, 0, 3);
		StructureUtils.setBlock(world, x + 6, y + 7, z + 3, Blocks.AIR, 0, 3);
		StructureUtils.setBlock(world, x + 7, y + 7, z + 3, Blocks.AIR, 0, 3);
		StructureUtils.setBlock(world, x + 8, y + 7, z + 3, Blocks.OAK_FENCE, 0, 3);
		StructureUtils.setBlock(world, x + 0, y + 7, z + 4, Blocks.COBBLESTONE, 0, 3);
		StructureUtils.setBlock(world, x + 1, y + 7, z + 4, Blocks.COBBLESTONE, 0, 3);
		StructureUtils.setBlock(world, x + 2, y + 7, z + 4, Blocks.COBBLESTONE, 0, 3);
		StructureUtils.setBlock(world, x + 3, y + 7, z + 4, Blocks.COBBLESTONE, 0, 3);
		StructureUtils.setBlock(world, x + 4, y + 7, z + 4, Blocks.COBBLESTONE, 0, 3);
		StructureUtils.setBlock(world, x + 5, y + 7, z + 4, Blocks.COBBLESTONE, 0, 3);
		StructureUtils.setBlock(world, x + 6, y + 7, z + 4, Blocks.OAK_DOOR, 1, 3);
		StructureUtils.setBlock(world, x + 6, y + 8, z + 4, Blocks.OAK_DOOR, 8, 3);
		StructureUtils.setBlock(world, x + 7, y + 7, z + 4, Blocks.COBBLESTONE, 0, 3);
		StructureUtils.setBlock(world, x + 8, y + 7, z + 4, Blocks.COBBLESTONE, 0, 3);
		StructureUtils.setBlock(world, x + 0, y + 7, z + 5, Blocks.COBBLESTONE, 0, 3);
		StructureUtils.setBlock(world, x + 1, y + 7, z + 5, Blocks.PLANKS, 0, 3);
		StructureUtils.setBlock(world, x + 2, y + 7, z + 5, Blocks.OAK_STAIRS, 1, 3);
		StructureUtils.setBlock(world, x + 3, y + 7, z + 5, Blocks.AIR, 0, 3);
		StructureUtils.setBlock(world, x + 4, y + 7, z + 5, Blocks.AIR, 0, 3);
		StructureUtils.setBlock(world, x + 5, y + 7, z + 5, Blocks.AIR, 0, 3);
		StructureUtils.setBlock(world, x + 6, y + 7, z + 5, Blocks.AIR, 0, 3);
		StructureUtils.setBlock(world, x + 7, y + 7, z + 5, Blocks.AIR, 0, 3);
		StructureUtils.setBlock(world, x + 8, y + 7, z + 5, Blocks.COBBLESTONE, 0, 3);
		StructureUtils.setBlock(world, x + 0, y + 7, z + 6, Blocks.COBBLESTONE, 0, 3);
		StructureUtils.setBlock(world, x + 1, y + 7, z + 6, Blocks.OAK_STAIRS, 3, 3);
		StructureUtils.setBlock(world, x + 2, y + 7, z + 6, Blocks.OAK_FENCE, 0, 3);
		StructureUtils.setBlock(world, x + 3, y + 7, z + 6, Blocks.AIR, 0, 3);
		StructureUtils.setBlock(world, x + 4, y + 7, z + 6, Blocks.AIR, 0, 3);
		StructureUtils.setBlock(world, x + 5, y + 7, z + 6, Blocks.AIR, 0, 3);
		StructureUtils.setBlock(world, x + 6, y + 7, z + 6, Blocks.DOUBLE_STONE_SLAB, 0, 3);
		StructureUtils.setBlock(world, x + 7, y + 7, z + 6, Blocks.OAK_FENCE_GATE, 0, 3);
		StructureUtils.setBlock(world, x + 8, y + 7, z + 6, Blocks.COBBLESTONE, 0, 3);
		StructureUtils.setBlock(world, x + 0, y + 7, z + 7, Blocks.COBBLESTONE, 0, 3);
		StructureUtils.setBlock(world, x + 2, y + 7, z + 7, Blocks.AIR, 0, 3);
		StructureUtils.setBlock(world, x + 3, y + 7, z + 7, Blocks.AIR, 0, 3);
		StructureUtils.setBlock(world, x + 4, y + 7, z + 7, Blocks.AIR, 0, 3);
		StructureUtils.setBlock(world, x + 5, y + 7, z + 7, Blocks.AIR, 0, 3);
		StructureUtils.setBlock(world, x + 6, y + 7, z + 7, Blocks.DOUBLE_STONE_SLAB, 0, 3);
		StructureUtils.setBlock(world, x + 7, y + 7, z + 7, Blocks.AIR, 0, 3);
		StructureUtils.setBlock(world, x + 8, y + 7, z + 7, Blocks.COBBLESTONE, 0, 3);
		StructureUtils.setBlock(world, x + 0, y + 7, z + 8, Blocks.COBBLESTONE, 0, 3);
		StructureUtils.setBlock(world, x + 1, y + 7, z + 8, Blocks.CHEST, 5, 3);
		StructureUtils.setBlock(world, x + 2, y + 7, z + 8, Blocks.AIR, 0, 3);
		StructureUtils.setBlock(world, x + 3, y + 7, z + 8, Blocks.AIR, 0, 3);
		StructureUtils.setBlock(world, x + 4, y + 7, z + 8, Blocks.AIR, 0, 3);
		StructureUtils.setBlock(world, x + 5, y + 7, z + 8, Blocks.AIR, 0, 3);
		StructureUtils.setBlock(world, x + 6, y + 7, z + 8, Blocks.DOUBLE_STONE_SLAB, 0, 3);
		StructureUtils.setBlock(world, x + 8, y + 7, z + 8, Blocks.COBBLESTONE, 0, 3);
		StructureUtils.setBlock(world, x + 0, y + 7, z + 9, Blocks.COBBLESTONE, 0, 3);
		StructureUtils.setBlock(world, x + 1, y + 7, z + 9, Blocks.COBBLESTONE, 0, 3);
		StructureUtils.setBlock(world, x + 2, y + 7, z + 9, Blocks.OAK_DOOR, 3, 3);
		StructureUtils.setBlock(world, x + 2, y + 8, z + 9, Blocks.OAK_DOOR, 9, 3);
		StructureUtils.setBlock(world, x + 3, y + 7, z + 9, Blocks.COBBLESTONE, 0, 3);
		StructureUtils.setBlock(world, x + 4, y + 7, z + 9, Blocks.COBBLESTONE, 0, 3);
		StructureUtils.setBlock(world, x + 5, y + 7, z + 9, Blocks.COBBLESTONE, 0, 3);
		StructureUtils.setBlock(world, x + 6, y + 7, z + 9, Blocks.COBBLESTONE, 0, 3);
		StructureUtils.setBlock(world, x + 7, y + 7, z + 9, Blocks.COBBLESTONE, 0, 3);
		StructureUtils.setBlock(world, x + 8, y + 7, z + 9, Blocks.COBBLESTONE, 0, 3);
		StructureUtils.setBlock(world, x + 3, y + 8, z + 1, Blocks.AIR, 0, 3);
		StructureUtils.setBlock(world, x + 4, y + 8, z + 1, Blocks.AIR, 0, 3);
		StructureUtils.setBlock(world, x + 5, y + 8, z + 1, Blocks.AIR, 0, 3);
		StructureUtils.setBlock(world, x + 6, y + 8, z + 1, Blocks.AIR, 0, 3);
		StructureUtils.setBlock(world, x + 7, y + 8, z + 1, Blocks.AIR, 0, 3);
		StructureUtils.setBlock(world, x + 3, y + 8, z + 2, Blocks.AIR, 0, 3);
		StructureUtils.setBlock(world, x + 4, y + 8, z + 2, Blocks.AIR, 0, 3);
		StructureUtils.setBlock(world, x + 5, y + 8, z + 2, Blocks.AIR, 0, 3);
		StructureUtils.setBlock(world, x + 6, y + 8, z + 2, Blocks.AIR, 0, 3);
		StructureUtils.setBlock(world, x + 7, y + 8, z + 2, Blocks.AIR, 0, 3);
		StructureUtils.setBlock(world, x + 3, y + 8, z + 3, Blocks.AIR, 0, 3);
		StructureUtils.setBlock(world, x + 4, y + 8, z + 3, Blocks.AIR, 0, 3);
		StructureUtils.setBlock(world, x + 5, y + 8, z + 3, Blocks.AIR, 0, 3);
		StructureUtils.setBlock(world, x + 6, y + 8, z + 3, Blocks.AIR, 0, 3);
		StructureUtils.setBlock(world, x + 7, y + 8, z + 3, Blocks.AIR, 0, 3);
		StructureUtils.setBlock(world, x + 0, y + 8, z + 4, Blocks.COBBLESTONE, 0, 3);
		StructureUtils.setBlock(world, x + 1, y + 8, z + 4, Blocks.PLANKS, 0, 3);
		StructureUtils.setBlock(world, x + 2, y + 8, z + 4, Blocks.GLASS, 0, 3);
		StructureUtils.setBlock(world, x + 3, y + 8, z + 4, Blocks.GLASS, 0, 3);
		StructureUtils.setBlock(world, x + 4, y + 8, z + 4, Blocks.PLANKS, 0, 3);
		StructureUtils.setBlock(world, x + 5, y + 8, z + 4, Blocks.PLANKS, 0, 3);
		StructureUtils.setBlock(world, x + 7, y + 8, z + 4, Blocks.PLANKS, 0, 3);
		StructureUtils.setBlock(world, x + 8, y + 8, z + 4, Blocks.COBBLESTONE, 0, 3);
		StructureUtils.setBlock(world, x + 0, y + 8, z + 5, Blocks.LOG, 0, 3);
		StructureUtils.setBlock(world, x + 1, y + 8, z + 5, Blocks.AIR, 0, 3);
		StructureUtils.setBlock(world, x + 2, y + 8, z + 5, Blocks.AIR, 0, 3);
		StructureUtils.setBlock(world, x + 3, y + 8, z + 5, Blocks.AIR, 0, 3);
		StructureUtils.setBlock(world, x + 4, y + 8, z + 5, Blocks.AIR, 0, 3);
		StructureUtils.setBlock(world, x + 5, y + 8, z + 5, Blocks.AIR, 0, 3);
		StructureUtils.setBlock(world, x + 6, y + 8, z + 5, Blocks.AIR, 0, 3);
		StructureUtils.setBlock(world, x + 7, y + 8, z + 5, Blocks.AIR, 0, 3);
		StructureUtils.setBlock(world, x + 8, y + 8, z + 5, Blocks.LOG, 0, 3);
		StructureUtils.setBlock(world, x + 0, y + 8, z + 6, Blocks.GLASS, 0, 3);
		StructureUtils.setBlock(world, x + 1, y + 8, z + 6, Blocks.AIR, 0, 3);
		StructureUtils.setBlock(world, x + 2, y + 8, z + 6, Blocks.WOODEN_PRESSURE_PLATE, 0, 3);
		StructureUtils.setBlock(world, x + 3, y + 8, z + 6, Blocks.AIR, 0, 3);
		StructureUtils.setBlock(world, x + 4, y + 8, z + 6, Blocks.AIR, 0, 3);
		StructureUtils.setBlock(world, x + 5, y + 8, z + 6, Blocks.AIR, 0, 3);
		StructureUtils.setBlock(world, x + 6, y + 8, z + 6, Blocks.AIR, 0, 3);
		StructureUtils.setBlock(world, x + 7, y + 8, z + 6, Blocks.AIR, 0, 3);
		StructureUtils.setBlock(world, x + 8, y + 8, z + 6, Blocks.GLASS, 0, 3);
		StructureUtils.setBlock(world, x + 0, y + 8, z + 7, Blocks.GLASS, 0, 3);
		StructureUtils.setBlock(world, x + 1, y + 8, z + 7, Blocks.AIR, 0, 3);
		StructureUtils.setBlock(world, x + 2, y + 8, z + 7, Blocks.AIR, 0, 3);
		StructureUtils.setBlock(world, x + 3, y + 8, z + 7, Blocks.AIR, 0, 3);
		StructureUtils.setBlock(world, x + 4, y + 8, z + 7, Blocks.AIR, 0, 3);
		StructureUtils.setBlock(world, x + 5, y + 8, z + 7, Blocks.AIR, 0, 3);
		StructureUtils.setBlock(world, x + 6, y + 8, z + 7, Blocks.AIR, 0, 3);
		StructureUtils.setBlock(world, x + 7, y + 8, z + 7, Blocks.AIR, 0, 3);
		StructureUtils.setBlock(world, x + 8, y + 8, z + 7, Blocks.GLASS, 0, 3);
		StructureUtils.setBlock(world, x + 0, y + 8, z + 8, Blocks.LOG, 0, 3);
		StructureUtils.setBlock(world, x + 1, y + 8, z + 8, Blocks.AIR, 0, 3);
		StructureUtils.setBlock(world, x + 2, y + 8, z + 8, Blocks.AIR, 0, 3);
		StructureUtils.setBlock(world, x + 3, y + 8, z + 8, Blocks.AIR, 0, 3);
		StructureUtils.setBlock(world, x + 4, y + 8, z + 8, Blocks.AIR, 0, 3);
		StructureUtils.setBlock(world, x + 5, y + 8, z + 8, Blocks.AIR, 0, 3);
		StructureUtils.setBlock(world, x + 6, y + 8, z + 8, Blocks.AIR, 0, 3);
		StructureUtils.setBlock(world, x + 7, y + 8, z + 8, Blocks.AIR, 0, 3);
		StructureUtils.setBlock(world, x + 8, y + 8, z + 8, Blocks.LOG, 0, 3);
		StructureUtils.setBlock(world, x + 0, y + 8, z + 9, Blocks.COBBLESTONE, 0, 3);
		StructureUtils.setBlock(world, x + 1, y + 8, z + 9, Blocks.PLANKS, 0, 3);
		StructureUtils.setBlock(world, x + 3, y + 8, z + 9, Blocks.PLANKS, 0, 3);
		StructureUtils.setBlock(world, x + 4, y + 8, z + 9, Blocks.PLANKS, 0, 3);
		StructureUtils.setBlock(world, x + 5, y + 8, z + 9, Blocks.GLASS, 0, 3);
		StructureUtils.setBlock(world, x + 6, y + 8, z + 9, Blocks.GLASS, 0, 3);
		StructureUtils.setBlock(world, x + 7, y + 8, z + 9, Blocks.PLANKS, 0, 3);
		StructureUtils.setBlock(world, x + 8, y + 8, z + 9, Blocks.COBBLESTONE, 0, 3);
		StructureUtils.setBlock(world, x + 0, y + 9, z + 3, Blocks.OAK_STAIRS, 2, 3);
		StructureUtils.setBlock(world, x + 1, y + 9, z + 3, Blocks.OAK_STAIRS, 2, 3);
		StructureUtils.setBlock(world, x + 2, y + 9, z + 3, Blocks.OAK_STAIRS, 2, 3);
		StructureUtils.setBlock(world, x + 3, y + 9, z + 3, Blocks.OAK_STAIRS, 2, 3);
		StructureUtils.setBlock(world, x + 4, y + 9, z + 3, Blocks.OAK_STAIRS, 2, 3);
		StructureUtils.setBlock(world, x + 5, y + 9, z + 3, Blocks.OAK_STAIRS, 2, 3);
		StructureUtils.setBlock(world, x + 6, y + 9, z + 3, Blocks.OAK_STAIRS, 2, 3);
		StructureUtils.setBlock(world, x + 7, y + 9, z + 3, Blocks.OAK_STAIRS, 2, 3);
		StructureUtils.setBlock(world, x + 8, y + 9, z + 3, Blocks.OAK_STAIRS, 2, 3);
		StructureUtils.setBlock(world, x + 0, y + 9, z + 4, Blocks.COBBLESTONE, 0, 3);
		StructureUtils.setBlock(world, x + 1, y + 9, z + 4, Blocks.PLANKS, 0, 3);
		StructureUtils.setBlock(world, x + 2, y + 9, z + 4, Blocks.PLANKS, 0, 3);
		StructureUtils.setBlock(world, x + 3, y + 9, z + 4, Blocks.PLANKS, 0, 3);
		StructureUtils.setBlock(world, x + 4, y + 9, z + 4, Blocks.PLANKS, 0, 3);
		StructureUtils.setBlock(world, x + 5, y + 9, z + 4, Blocks.PLANKS, 0, 3);
		StructureUtils.setBlock(world, x + 6, y + 9, z + 4, Blocks.PLANKS, 0, 3);
		StructureUtils.setBlock(world, x + 7, y + 9, z + 4, Blocks.PLANKS, 0, 3);
		StructureUtils.setBlock(world, x + 8, y + 9, z + 4, Blocks.COBBLESTONE, 0, 3);
		StructureUtils.setBlock(world, x + 0, y + 9, z + 5, Blocks.COBBLESTONE, 0, 3);
		StructureUtils.setBlock(world, x + 1, y + 9, z + 5, Blocks.AIR, 0, 3);
		StructureUtils.setBlock(world, x + 2, y + 9, z + 5, Blocks.AIR, 0, 3);
		StructureUtils.setBlock(world, x + 3, y + 9, z + 5, Blocks.AIR, 0, 3);
		StructureUtils.setBlock(world, x + 4, y + 9, z + 5, Blocks.AIR, 0, 3);
		StructureUtils.setBlock(world, x + 5, y + 9, z + 5, Blocks.AIR, 0, 3);
		StructureUtils.setBlock(world, x + 6, y + 9, z + 5, Blocks.AIR, 0, 3);
		StructureUtils.setBlock(world, x + 7, y + 9, z + 5, Blocks.AIR, 0, 3);
		StructureUtils.setBlock(world, x + 8, y + 9, z + 5, Blocks.COBBLESTONE, 0, 3);
		StructureUtils.setBlock(world, x + 0, y + 9, z + 6, Blocks.COBBLESTONE, 0, 3);
		StructureUtils.setBlock(world, x + 1, y + 9, z + 6, Blocks.AIR, 0, 3);
		StructureUtils.setBlock(world, x + 2, y + 9, z + 6, Blocks.AIR, 0, 3);
		StructureUtils.setBlock(world, x + 3, y + 9, z + 6, Blocks.AIR, 0, 3);
		StructureUtils.setBlock(world, x + 4, y + 9, z + 6, Blocks.AIR, 0, 3);
		StructureUtils.setBlock(world, x + 5, y + 9, z + 6, Blocks.AIR, 0, 3);
		StructureUtils.setBlock(world, x + 6, y + 9, z + 6, Blocks.AIR, 0, 3);
		StructureUtils.setBlock(world, x + 7, y + 9, z + 6, Blocks.AIR, 0, 3);
		StructureUtils.setBlock(world, x + 8, y + 9, z + 6, Blocks.COBBLESTONE, 0, 3);
		StructureUtils.setBlock(world, x + 0, y + 9, z + 7, Blocks.COBBLESTONE, 0, 3);
		StructureUtils.setBlock(world, x + 1, y + 9, z + 7, Blocks.AIR, 0, 3);
		StructureUtils.setBlock(world, x + 2, y + 9, z + 7, Blocks.AIR, 0, 3);
		StructureUtils.setBlock(world, x + 3, y + 9, z + 7, Blocks.AIR, 0, 3);
		StructureUtils.setBlock(world, x + 4, y + 9, z + 7, Blocks.AIR, 0, 3);
		StructureUtils.setBlock(world, x + 5, y + 9, z + 7, Blocks.AIR, 0, 3);
		StructureUtils.setBlock(world, x + 6, y + 9, z + 7, Blocks.AIR, 0, 3);
		StructureUtils.setBlock(world, x + 7, y + 9, z + 7, Blocks.AIR, 0, 3);
		StructureUtils.setBlock(world, x + 8, y + 9, z + 7, Blocks.COBBLESTONE, 0, 3);
		StructureUtils.setBlock(world, x + 0, y + 9, z + 8, Blocks.COBBLESTONE, 0, 3);
		StructureUtils.setBlock(world, x + 1, y + 9, z + 8, Blocks.AIR, 0, 3);
		StructureUtils.setBlock(world, x + 2, y + 9, z + 8, Blocks.AIR, 0, 3);
		StructureUtils.setBlock(world, x + 3, y + 9, z + 8, Blocks.AIR, 0, 3);
		StructureUtils.setBlock(world, x + 4, y + 9, z + 8, Blocks.AIR, 0, 3);
		StructureUtils.setBlock(world, x + 5, y + 9, z + 8, Blocks.AIR, 0, 3);
		StructureUtils.setBlock(world, x + 6, y + 9, z + 8, Blocks.AIR, 0, 3);
		StructureUtils.setBlock(world, x + 7, y + 9, z + 8, Blocks.AIR, 0, 3);
		StructureUtils.setBlock(world, x + 8, y + 9, z + 8, Blocks.COBBLESTONE, 0, 3);
		StructureUtils.setBlock(world, x + 0, y + 9, z + 9, Blocks.COBBLESTONE, 0, 3);
		StructureUtils.setBlock(world, x + 1, y + 9, z + 9, Blocks.PLANKS, 0, 3);
		StructureUtils.setBlock(world, x + 2, y + 9, z + 9, Blocks.PLANKS, 0, 3);
		StructureUtils.setBlock(world, x + 3, y + 9, z + 9, Blocks.PLANKS, 0, 3);
		StructureUtils.setBlock(world, x + 4, y + 9, z + 9, Blocks.PLANKS, 0, 3);
		StructureUtils.setBlock(world, x + 5, y + 9, z + 9, Blocks.PLANKS, 0, 3);
		StructureUtils.setBlock(world, x + 6, y + 9, z + 9, Blocks.PLANKS, 0, 3);
		StructureUtils.setBlock(world, x + 7, y + 9, z + 9, Blocks.PLANKS, 0, 3);
		StructureUtils.setBlock(world, x + 8, y + 9, z + 9, Blocks.COBBLESTONE, 0, 3);
		StructureUtils.setBlock(world, x + 0, y + 9, z + 10, Blocks.OAK_STAIRS, 3, 3);
		StructureUtils.setBlock(world, x + 1, y + 9, z + 10, Blocks.OAK_STAIRS, 3, 3);
		StructureUtils.setBlock(world, x + 2, y + 9, z + 10, Blocks.OAK_STAIRS, 3, 3);
		StructureUtils.setBlock(world, x + 3, y + 9, z + 10, Blocks.OAK_STAIRS, 3, 3);
		StructureUtils.setBlock(world, x + 4, y + 9, z + 10, Blocks.OAK_STAIRS, 3, 3);
		StructureUtils.setBlock(world, x + 5, y + 9, z + 10, Blocks.OAK_STAIRS, 3, 3);
		StructureUtils.setBlock(world, x + 6, y + 9, z + 10, Blocks.OAK_STAIRS, 3, 3);
		StructureUtils.setBlock(world, x + 7, y + 9, z + 10, Blocks.OAK_STAIRS, 3, 3);
		StructureUtils.setBlock(world, x + 8, y + 9, z + 10, Blocks.OAK_STAIRS, 3, 3);
		StructureUtils.setBlock(world, x + 0, y + 10, z + 4, Blocks.OAK_STAIRS, 2, 3);
		StructureUtils.setBlock(world, x + 1, y + 10, z + 4, Blocks.OAK_STAIRS, 2, 3);
		StructureUtils.setBlock(world, x + 2, y + 10, z + 4, Blocks.OAK_STAIRS, 2, 3);
		StructureUtils.setBlock(world, x + 3, y + 10, z + 4, Blocks.OAK_STAIRS, 2, 3);
		StructureUtils.setBlock(world, x + 4, y + 10, z + 4, Blocks.OAK_STAIRS, 2, 3);
		StructureUtils.setBlock(world, x + 5, y + 10, z + 4, Blocks.OAK_STAIRS, 2, 3);
		StructureUtils.setBlock(world, x + 6, y + 10, z + 4, Blocks.OAK_STAIRS, 2, 3);
		StructureUtils.setBlock(world, x + 7, y + 10, z + 4, Blocks.OAK_STAIRS, 2, 3);
		StructureUtils.setBlock(world, x + 8, y + 10, z + 4, Blocks.OAK_STAIRS, 2, 3);
		StructureUtils.setBlock(world, x + 0, y + 10, z + 5, Blocks.PLANKS, 0, 3);
		StructureUtils.setBlock(world, x + 1, y + 10, z + 5, Blocks.PLANKS, 0, 3);
		StructureUtils.setBlock(world, x + 2, y + 10, z + 5, Blocks.PLANKS, 0, 3);
		StructureUtils.setBlock(world, x + 3, y + 10, z + 5, Blocks.PLANKS, 0, 3);
		StructureUtils.setBlock(world, x + 4, y + 10, z + 5, Blocks.PLANKS, 0, 3);
		StructureUtils.setBlock(world, x + 5, y + 10, z + 5, Blocks.PLANKS, 0, 3);
		StructureUtils.setBlock(world, x + 6, y + 10, z + 5, Blocks.PLANKS, 0, 3);
		StructureUtils.setBlock(world, x + 7, y + 10, z + 5, Blocks.PLANKS, 0, 3);
		StructureUtils.setBlock(world, x + 8, y + 10, z + 5, Blocks.PLANKS, 0, 3);
		StructureUtils.setBlock(world, x + 0, y + 10, z + 6, Blocks.PLANKS, 0, 3);
		StructureUtils.setBlock(world, x + 1, y + 10, z + 6, Blocks.AIR, 0, 3);
		StructureUtils.setBlock(world, x + 2, y + 10, z + 6, Blocks.AIR, 0, 3);
		StructureUtils.setBlock(world, x + 3, y + 10, z + 6, Blocks.AIR, 0, 3);
		StructureUtils.setBlock(world, x + 4, y + 10, z + 6, Blocks.AIR, 0, 3);
		StructureUtils.setBlock(world, x + 5, y + 10, z + 6, Blocks.AIR, 0, 3);
		StructureUtils.setBlock(world, x + 6, y + 10, z + 6, Blocks.AIR, 0, 3);
		StructureUtils.setBlock(world, x + 7, y + 10, z + 6, Blocks.AIR, 0, 3);
		StructureUtils.setBlock(world, x + 8, y + 10, z + 6, Blocks.PLANKS, 0, 3);
		StructureUtils.setBlock(world, x + 0, y + 10, z + 7, Blocks.PLANKS, 0, 3);
		StructureUtils.setBlock(world, x + 1, y + 10, z + 7, Blocks.AIR, 0, 3);
		StructureUtils.setBlock(world, x + 2, y + 10, z + 7, Blocks.AIR, 0, 3);
		StructureUtils.setBlock(world, x + 3, y + 10, z + 7, Blocks.AIR, 0, 3);
		StructureUtils.setBlock(world, x + 4, y + 10, z + 7, Blocks.AIR, 0, 3);
		StructureUtils.setBlock(world, x + 5, y + 10, z + 7, Blocks.AIR, 0, 3);
		StructureUtils.setBlock(world, x + 6, y + 10, z + 7, Blocks.AIR, 0, 3);
		StructureUtils.setBlock(world, x + 7, y + 10, z + 7, Blocks.AIR, 0, 3);
		StructureUtils.setBlock(world, x + 8, y + 10, z + 7, Blocks.PLANKS, 0, 3);
		StructureUtils.setBlock(world, x + 0, y + 10, z + 8, Blocks.PLANKS, 0, 3);
		StructureUtils.setBlock(world, x + 1, y + 10, z + 8, Blocks.PLANKS, 0, 3);
		StructureUtils.setBlock(world, x + 2, y + 10, z + 8, Blocks.PLANKS, 0, 3);
		StructureUtils.setBlock(world, x + 3, y + 10, z + 8, Blocks.PLANKS, 0, 3);
		StructureUtils.setBlock(world, x + 4, y + 10, z + 8, Blocks.PLANKS, 0, 3);
		StructureUtils.setBlock(world, x + 5, y + 10, z + 8, Blocks.PLANKS, 0, 3);
		StructureUtils.setBlock(world, x + 6, y + 10, z + 8, Blocks.PLANKS, 0, 3);
		StructureUtils.setBlock(world, x + 7, y + 10, z + 8, Blocks.PLANKS, 0, 3);
		StructureUtils.setBlock(world, x + 8, y + 10, z + 8, Blocks.PLANKS, 0, 3);
		StructureUtils.setBlock(world, x + 0, y + 10, z + 9, Blocks.OAK_STAIRS, 3, 3);
		StructureUtils.setBlock(world, x + 1, y + 10, z + 9, Blocks.OAK_STAIRS, 3, 3);
		StructureUtils.setBlock(world, x + 2, y + 10, z + 9, Blocks.OAK_STAIRS, 3, 3);
		StructureUtils.setBlock(world, x + 3, y + 10, z + 9, Blocks.OAK_STAIRS, 3, 3);
		StructureUtils.setBlock(world, x + 4, y + 10, z + 9, Blocks.OAK_STAIRS, 3, 3);
		StructureUtils.setBlock(world, x + 5, y + 10, z + 9, Blocks.OAK_STAIRS, 3, 3);
		StructureUtils.setBlock(world, x + 6, y + 10, z + 9, Blocks.OAK_STAIRS, 3, 3);
		StructureUtils.setBlock(world, x + 7, y + 10, z + 9, Blocks.OAK_STAIRS, 3, 3);
		StructureUtils.setBlock(world, x + 8, y + 10, z + 9, Blocks.OAK_STAIRS, 3, 3);
		StructureUtils.setBlock(world, x + 0, y + 11, z + 5, Blocks.OAK_STAIRS, 2, 3);
		StructureUtils.setBlock(world, x + 1, y + 11, z + 5, Blocks.OAK_STAIRS, 2, 3);
		StructureUtils.setBlock(world, x + 2, y + 11, z + 5, Blocks.OAK_STAIRS, 2, 3);
		StructureUtils.setBlock(world, x + 3, y + 11, z + 5, Blocks.OAK_STAIRS, 2, 3);
		StructureUtils.setBlock(world, x + 4, y + 11, z + 5, Blocks.OAK_STAIRS, 2, 3);
		StructureUtils.setBlock(world, x + 5, y + 11, z + 5, Blocks.OAK_STAIRS, 2, 3);
		StructureUtils.setBlock(world, x + 6, y + 11, z + 5, Blocks.OAK_STAIRS, 2, 3);
		StructureUtils.setBlock(world, x + 7, y + 11, z + 5, Blocks.OAK_STAIRS, 2, 3);
		StructureUtils.setBlock(world, x + 8, y + 11, z + 5, Blocks.OAK_STAIRS, 2, 3);
		StructureUtils.setBlock(world, x + 0, y + 11, z + 6, Blocks.PLANKS, 0, 3);
		StructureUtils.setBlock(world, x + 1, y + 11, z + 6, Blocks.PLANKS, 0, 3);
		StructureUtils.setBlock(world, x + 2, y + 11, z + 6, Blocks.PLANKS, 0, 3);
		StructureUtils.setBlock(world, x + 3, y + 11, z + 6, Blocks.PLANKS, 0, 3);
		StructureUtils.setBlock(world, x + 4, y + 11, z + 6, Blocks.PLANKS, 0, 3);
		StructureUtils.setBlock(world, x + 5, y + 11, z + 6, Blocks.PLANKS, 0, 3);
		StructureUtils.setBlock(world, x + 6, y + 11, z + 6, Blocks.PLANKS, 0, 3);
		StructureUtils.setBlock(world, x + 7, y + 11, z + 6, Blocks.PLANKS, 0, 3);
		StructureUtils.setBlock(world, x + 8, y + 11, z + 6, Blocks.PLANKS, 0, 3);
		StructureUtils.setBlock(world, x + 0, y + 11, z + 7, Blocks.PLANKS, 0, 3);
		StructureUtils.setBlock(world, x + 1, y + 11, z + 7, Blocks.PLANKS, 0, 3);
		StructureUtils.setBlock(world, x + 2, y + 11, z + 7, Blocks.PLANKS, 0, 3);
		StructureUtils.setBlock(world, x + 3, y + 11, z + 7, Blocks.PLANKS, 0, 3);
		StructureUtils.setBlock(world, x + 4, y + 11, z + 7, Blocks.PLANKS, 0, 3);
		StructureUtils.setBlock(world, x + 5, y + 11, z + 7, Blocks.PLANKS, 0, 3);
		StructureUtils.setBlock(world, x + 6, y + 11, z + 7, Blocks.PLANKS, 0, 3);
		StructureUtils.setBlock(world, x + 7, y + 11, z + 7, Blocks.PLANKS, 0, 3);
		StructureUtils.setBlock(world, x + 8, y + 11, z + 7, Blocks.PLANKS, 0, 3);
		StructureUtils.setBlock(world, x + 0, y + 11, z + 8, Blocks.OAK_STAIRS, 3, 3);
		StructureUtils.setBlock(world, x + 1, y + 11, z + 8, Blocks.OAK_STAIRS, 3, 3);
		StructureUtils.setBlock(world, x + 2, y + 11, z + 8, Blocks.OAK_STAIRS, 3, 3);
		StructureUtils.setBlock(world, x + 3, y + 11, z + 8, Blocks.OAK_STAIRS, 3, 3);
		StructureUtils.setBlock(world, x + 4, y + 11, z + 8, Blocks.OAK_STAIRS, 3, 3);
		StructureUtils.setBlock(world, x + 5, y + 11, z + 8, Blocks.OAK_STAIRS, 3, 3);
		StructureUtils.setBlock(world, x + 6, y + 11, z + 8, Blocks.OAK_STAIRS, 3, 3);
		StructureUtils.setBlock(world, x + 7, y + 11, z + 8, Blocks.OAK_STAIRS, 3, 3);
		StructureUtils.setBlock(world, x + 8, y + 11, z + 8, Blocks.OAK_STAIRS, 3, 3);
		StructureUtils.setBlock(world, x + 0, y + 12, z + 6, Blocks.OAK_STAIRS, 2, 3);
		StructureUtils.setBlock(world, x + 1, y + 12, z + 6, Blocks.OAK_STAIRS, 2, 3);
		StructureUtils.setBlock(world, x + 2, y + 12, z + 6, Blocks.OAK_STAIRS, 2, 3);
		StructureUtils.setBlock(world, x + 3, y + 12, z + 6, Blocks.OAK_STAIRS, 2, 3);
		StructureUtils.setBlock(world, x + 4, y + 12, z + 6, Blocks.OAK_STAIRS, 2, 3);
		StructureUtils.setBlock(world, x + 5, y + 12, z + 6, Blocks.OAK_STAIRS, 2, 3);
		StructureUtils.setBlock(world, x + 6, y + 12, z + 6, Blocks.OAK_STAIRS, 2, 3);
		StructureUtils.setBlock(world, x + 7, y + 12, z + 6, Blocks.OAK_STAIRS, 2, 3);
		StructureUtils.setBlock(world, x + 8, y + 12, z + 6, Blocks.OAK_STAIRS, 2, 3);
		StructureUtils.setBlock(world, x + 0, y + 12, z + 7, Blocks.OAK_STAIRS, 3, 3);
		StructureUtils.setBlock(world, x + 1, y + 12, z + 7, Blocks.OAK_STAIRS, 3, 3);
		StructureUtils.setBlock(world, x + 2, y + 12, z + 7, Blocks.OAK_STAIRS, 3, 3);
		StructureUtils.setBlock(world, x + 3, y + 12, z + 7, Blocks.OAK_STAIRS, 3, 3);
		StructureUtils.setBlock(world, x + 4, y + 12, z + 7, Blocks.OAK_STAIRS, 3, 3);
		StructureUtils.setBlock(world, x + 5, y + 12, z + 7, Blocks.OAK_STAIRS, 3, 3);
		StructureUtils.setBlock(world, x + 6, y + 12, z + 7, Blocks.OAK_STAIRS, 3, 3);
		StructureUtils.setBlock(world, x + 7, y + 12, z + 7, Blocks.OAK_STAIRS, 3, 3);
		StructureUtils.setBlock(world, x + 8, y + 12, z + 7, Blocks.OAK_STAIRS, 3, 3);
		generate_r02_last(world, rand, x, y, z);
		return true;

	}

	public static boolean generate_r02_last(World world, Random rand, int x, int y, int z) {
		StructureUtils.setBlock(world, x + 7, y + 1, z + 8, Blocks.LADDER, 2, 3);
		StructureUtils.setBlock(world, x + 7, y + 2, z + 8, Blocks.LADDER, 2, 3);
		StructureUtils.setBlock(world, x + 7, y + 3, z + 8, Blocks.LADDER, 2, 3);
		StructureUtils.setBlock(world, x + 7, y + 4, z + 8, Blocks.LADDER, 2, 3);
		StructureUtils.setBlock(world, x + 7, y + 5, z + 7, Blocks.STONE_BUTTON, 0, 3);
		StructureUtils.setBlock(world, x + 7, y + 5, z + 8, Blocks.LADDER, 2, 3);
		StructureUtils.setBlock(world, x + 7, y + 7, z + 8, Blocks.STONE_BUTTON, 4, 3);
		makeVillager(world, new BlockPos(x + 7, y + 7, z + 8));
		return true;
	}

	public static boolean generateEast(World world, Random rand, int x, int y, int z) {
		StructureUtils.setBlock(world, x + 0, y + 0, z + 6, ModBlocks.laboratory_block, 0, 3);
		StructureUtils.setBlock(world, x + 0, y + 0, z + 5, ModBlocks.laboratory_block, 0, 3);
		StructureUtils.setBlock(world, x + 0, y + 0, z + 4, ModBlocks.laboratory_block, 0, 3);
		StructureUtils.setBlock(world, x + 0, y + 0, z + 3, ModBlocks.laboratory_block, 0, 3);
		StructureUtils.setBlock(world, x + 0, y + 0, z + 2, ModBlocks.laboratory_block, 0, 3);
		StructureUtils.setBlock(world, x + 1, y + 0, z + 6, ModBlocks.laboratory_block, 0, 3);
		StructureUtils.setBlock(world, x + 1, y + 0, z + 5, Blocks.GRASS_PATH, 0, 3);
		StructureUtils.setBlock(world, x + 1, y + 0, z + 4, Blocks.GRASS_PATH, 0, 3);
		StructureUtils.setBlock(world, x + 1, y + 0, z + 3, Blocks.GRASS_PATH, 0, 3);
		StructureUtils.setBlock(world, x + 1, y + 0, z + 2, ModBlocks.laboratory_block, 0, 3);
		StructureUtils.setBlock(world, x + 2, y + 0, z + 6, ModBlocks.laboratory_block, 0, 3);
		StructureUtils.setBlock(world, x + 2, y + 0, z + 5, Blocks.GRASS_PATH, 0, 3);
		StructureUtils.setBlock(world, x + 2, y + 0, z + 4, Blocks.GRASS_PATH, 0, 3);
		StructureUtils.setBlock(world, x + 2, y + 0, z + 3, Blocks.GRASS_PATH, 0, 3);
		StructureUtils.setBlock(world, x + 2, y + 0, z + 2, ModBlocks.laboratory_block, 0, 3);
		StructureUtils.setBlock(world, x + 3, y + 0, z + 6, ModBlocks.laboratory_block, 0, 3);
		StructureUtils.setBlock(world, x + 3, y + 0, z + 5, Blocks.GRASS_PATH, 0, 3);
		StructureUtils.setBlock(world, x + 3, y + 0, z + 4, Blocks.GRASS_PATH, 0, 3);
		StructureUtils.setBlock(world, x + 3, y + 0, z + 3, Blocks.GRASS_PATH, 0, 3);
		StructureUtils.setBlock(world, x + 3, y + 0, z + 2, ModBlocks.laboratory_block, 0, 3);
		StructureUtils.setBlock(world, x + 4, y + 0, z + 8, ModBlocks.laboratory_block, 0, 3);
		StructureUtils.setBlock(world, x + 4, y + 0, z + 7, ModBlocks.laboratory_block, 0, 3);
		StructureUtils.setBlock(world, x + 4, y + 0, z + 6, ModBlocks.laboratory_block, 0, 3);
		StructureUtils.setBlock(world, x + 4, y + 0, z + 5, ModBlocks.laboratory_block, 0, 3);
		StructureUtils.setBlock(world, x + 4, y + 0, z + 4, ModBlocks.laboratory_block, 0, 3);
		StructureUtils.setBlock(world, x + 4, y + 0, z + 3, ModBlocks.laboratory_block, 0, 3);
		StructureUtils.setBlock(world, x + 4, y + 0, z + 2, ModBlocks.laboratory_block, 0, 3);
		StructureUtils.setBlock(world, x + 4, y + 0, z + 1, ModBlocks.laboratory_block, 0, 3);
		StructureUtils.setBlock(world, x + 4, y + 0, z + 0, ModBlocks.laboratory_block, 0, 3);
		StructureUtils.setBlock(world, x + 5, y + 0, z + 8, ModBlocks.laboratory_block, 0, 3);
		StructureUtils.setBlock(world, x + 5, y + 0, z + 7, ModBlocks.laboratory_block, 0, 3);
		StructureUtils.setBlock(world, x + 5, y + 0, z + 6, ModBlocks.laboratory_block, 0, 3);
		StructureUtils.setBlock(world, x + 5, y + 0, z + 5, ModBlocks.laboratory_block, 0, 3);
		StructureUtils.setBlock(world, x + 5, y + 0, z + 4, ModBlocks.laboratory_block, 0, 3);
		StructureUtils.setBlock(world, x + 5, y + 0, z + 3, ModBlocks.laboratory_block, 0, 3);
		StructureUtils.setBlock(world, x + 5, y + 0, z + 2, ModBlocks.laboratory_block, 0, 3);
		StructureUtils.setBlock(world, x + 5, y + 0, z + 1, ModBlocks.laboratory_block, 0, 3);
		StructureUtils.setBlock(world, x + 5, y + 0, z + 0, ModBlocks.laboratory_block, 0, 3);
		StructureUtils.setBlock(world, x + 6, y + 0, z + 8, ModBlocks.laboratory_block, 0, 3);
		StructureUtils.setBlock(world, x + 6, y + 0, z + 7, ModBlocks.laboratory_block, 0, 3);
		StructureUtils.setBlock(world, x + 6, y + 0, z + 6, ModBlocks.laboratory_block, 0, 3);
		StructureUtils.setBlock(world, x + 6, y + 0, z + 5, ModBlocks.laboratory_block, 0, 3);
		StructureUtils.setBlock(world, x + 6, y + 0, z + 4, ModBlocks.laboratory_block, 0, 3);
		StructureUtils.setBlock(world, x + 6, y + 0, z + 3, ModBlocks.laboratory_block, 0, 3);
		StructureUtils.setBlock(world, x + 6, y + 0, z + 2, ModBlocks.laboratory_block, 0, 3);
		StructureUtils.setBlock(world, x + 6, y + 0, z + 1, ModBlocks.laboratory_block, 0, 3);
		StructureUtils.setBlock(world, x + 6, y + 0, z + 0, ModBlocks.laboratory_block, 0, 3);
		StructureUtils.setBlock(world, x + 7, y + 0, z + 8, ModBlocks.laboratory_block, 0, 3);
		StructureUtils.setBlock(world, x + 7, y + 0, z + 7, ModBlocks.laboratory_block, 0, 3);
		StructureUtils.setBlock(world, x + 7, y + 0, z + 6, ModBlocks.laboratory_light_panel, 0, 3);
		StructureUtils.setBlock(world, x + 7, y + 0, z + 5, ModBlocks.laboratory_block, 0, 3);
		StructureUtils.setBlock(world, x + 7, y + 0, z + 4, ModBlocks.laboratory_block, 0, 3);
		StructureUtils.setBlock(world, x + 7, y + 0, z + 3, ModBlocks.laboratory_block, 0, 3);
		StructureUtils.setBlock(world, x + 7, y + 0, z + 2, ModBlocks.laboratory_light_panel, 0, 3);
		StructureUtils.setBlock(world, x + 7, y + 0, z + 1, ModBlocks.laboratory_block, 0, 3);
		StructureUtils.setBlock(world, x + 7, y + 0, z + 0, ModBlocks.laboratory_block, 0, 3);
		StructureUtils.setBlock(world, x + 8, y + 0, z + 8, ModBlocks.laboratory_block, 0, 3);
		StructureUtils.setBlock(world, x + 8, y + 0, z + 7, ModBlocks.laboratory_block, 0, 3);
		StructureUtils.setBlock(world, x + 8, y + 0, z + 6, ModBlocks.laboratory_block, 0, 3);
		StructureUtils.setBlock(world, x + 8, y + 0, z + 5, ModBlocks.laboratory_block, 0, 3);
		StructureUtils.setBlock(world, x + 8, y + 0, z + 4, ModBlocks.laboratory_block, 0, 3);
		StructureUtils.setBlock(world, x + 8, y + 0, z + 3, ModBlocks.laboratory_block, 0, 3);
		StructureUtils.setBlock(world, x + 8, y + 0, z + 2, ModBlocks.laboratory_block, 0, 3);
		StructureUtils.setBlock(world, x + 8, y + 0, z + 1, ModBlocks.laboratory_block, 0, 3);
		StructureUtils.setBlock(world, x + 8, y + 0, z + 0, ModBlocks.laboratory_block, 0, 3);
		StructureUtils.setBlock(world, x + 9, y + 0, z + 8, ModBlocks.laboratory_block, 0, 3);
		StructureUtils.setBlock(world, x + 9, y + 0, z + 7, ModBlocks.laboratory_block, 0, 3);
		StructureUtils.setBlock(world, x + 9, y + 0, z + 6, ModBlocks.laboratory_block, 0, 3);
		StructureUtils.setBlock(world, x + 9, y + 0, z + 5, ModBlocks.laboratory_block, 0, 3);
		StructureUtils.setBlock(world, x + 9, y + 0, z + 4, ModBlocks.laboratory_block, 0, 3);
		StructureUtils.setBlock(world, x + 9, y + 0, z + 3, ModBlocks.laboratory_block, 0, 3);
		StructureUtils.setBlock(world, x + 9, y + 0, z + 2, ModBlocks.laboratory_block, 0, 3);
		StructureUtils.setBlock(world, x + 9, y + 0, z + 1, ModBlocks.laboratory_block, 0, 3);
		StructureUtils.setBlock(world, x + 9, y + 0, z + 0, ModBlocks.laboratory_block, 0, 3);
		StructureUtils.setBlock(world, x + 0, y + 1, z + 6, ModBlocks.laboratory_block, 0, 3);
		StructureUtils.setBlock(world, x + 0, y + 1, z + 5, ModBlocks.laboratory_block, 0, 3);
		StructureUtils.setBlock(world, x + 0, y + 1, z + 4, ModBlocks.laboratory_block, 0, 3);
		StructureUtils.setBlock(world, x + 0, y + 1, z + 3, ModBlocks.laboratory_block, 0, 3);
		StructureUtils.setBlock(world, x + 0, y + 1, z + 2, ModBlocks.laboratory_block, 0, 3);
		StructureUtils.setBlock(world, x + 1, y + 1, z + 6, ModBlocks.laboratory_block, 0, 3);
		StructureUtils.setBlock(world, x + 1, y + 1, z + 5, Blocks.AIR, 0, 3);
		StructureUtils.setBlock(world, x + 1, y + 1, z + 4, Blocks.AIR, 0, 3);
		StructureUtils.setBlock(world, x + 1, y + 1, z + 3, Blocks.AIR, 0, 3);
		StructureUtils.setBlock(world, x + 1, y + 1, z + 2, ModBlocks.laboratory_block, 0, 3);
		StructureUtils.setBlock(world, x + 2, y + 1, z + 6, ModBlocks.laboratory_block, 0, 3);
		StructureUtils.setBlock(world, x + 2, y + 1, z + 5, Blocks.AIR, 0, 3);
		StructureUtils.setBlock(world, x + 2, y + 1, z + 4, Blocks.AIR, 0, 3);
		StructureUtils.setBlock(world, x + 2, y + 1, z + 3, Blocks.AIR, 0, 3);
		StructureUtils.setBlock(world, x + 2, y + 1, z + 2, ModBlocks.laboratory_block, 0, 3);
		StructureUtils.setBlock(world, x + 3, y + 1, z + 6, ModBlocks.laboratory_block, 0, 3);
		StructureUtils.setBlock(world, x + 3, y + 1, z + 5, Blocks.AIR, 0, 3);
		StructureUtils.setBlock(world, x + 3, y + 1, z + 4, Blocks.AIR, 0, 3);
		StructureUtils.setBlock(world, x + 3, y + 1, z + 3, Blocks.AIR, 0, 3);
		StructureUtils.setBlock(world, x + 3, y + 1, z + 2, ModBlocks.laboratory_block, 0, 3);
		StructureUtils.setBlock(world, x + 4, y + 1, z + 8, ModBlocks.laboratory_block, 0, 3);
		StructureUtils.setBlock(world, x + 4, y + 1, z + 7, ModBlocks.laboratory_block, 0, 3);
		StructureUtils.setBlock(world, x + 4, y + 1, z + 6, ModBlocks.laboratory_block, 0, 3);
		StructureUtils.setBlock(world, x + 4, y + 1, z + 5, Blocks.GLASS, 0, 3);
		StructureUtils.setBlock(world, x + 4, y + 1, z + 4, Blocks.GLASS, 0, 3);
		StructureUtils.setBlock(world, x + 4, y + 1, z + 3, Blocks.GLASS, 0, 3);
		StructureUtils.setBlock(world, x + 4, y + 1, z + 2, ModBlocks.laboratory_block, 0, 3);
		StructureUtils.setBlock(world, x + 4, y + 1, z + 1, ModBlocks.laboratory_block, 0, 3);
		StructureUtils.setBlock(world, x + 4, y + 1, z + 0, ModBlocks.laboratory_block, 0, 3);
		StructureUtils.setBlock(world, x + 5, y + 1, z + 8, ModBlocks.laboratory_block, 0, 3);
		StructureUtils.setBlock(world, x + 5, y + 1, z + 7, Blocks.CHEST, 2, 3);
		StructureUtils.setBlock(world, x + 5, y + 1, z + 6, Blocks.AIR, 0, 3);
		StructureUtils.setBlock(world, x + 5, y + 1, z + 5, Blocks.AIR, 0, 3);
		StructureUtils.setBlock(world, x + 5, y + 1, z + 4, Blocks.AIR, 0, 3);
		StructureUtils.setBlock(world, x + 5, y + 1, z + 3, Blocks.AIR, 0, 3);
		StructureUtils.setBlock(world, x + 5, y + 1, z + 2, Blocks.AIR, 0, 3);
		StructureUtils.setBlock(world, x + 5, y + 1, z + 1, Blocks.AIR, 0, 3);
		StructureUtils.setBlock(world, x + 5, y + 1, z + 0, ModBlocks.laboratory_block, 0, 3);
		StructureUtils.setBlock(world, x + 6, y + 1, z + 8, ModBlocks.laboratory_block, 0, 3);
		StructureUtils.setBlock(world, x + 6, y + 1, z + 7, Blocks.AIR, 0, 3);
		StructureUtils.setBlock(world, x + 6, y + 1, z + 6, Blocks.AIR, 0, 3);
		StructureUtils.setBlock(world, x + 6, y + 1, z + 5, Blocks.AIR, 0, 3);
		StructureUtils.setBlock(world, x + 6, y + 1, z + 4, Blocks.AIR, 0, 3);
		StructureUtils.setBlock(world, x + 6, y + 1, z + 3, Blocks.AIR, 0, 3);
		StructureUtils.setBlock(world, x + 6, y + 1, z + 2, Blocks.AIR, 0, 3);
		StructureUtils.setBlock(world, x + 6, y + 1, z + 1, ModBlocks.fossil_slicer, 4, 3);
		StructureUtils.setBlock(world, x + 6, y + 1, z + 0, ModBlocks.laboratory_block, 0, 3);
		StructureUtils.setBlock(world, x + 7, y + 1, z + 8, ModBlocks.laboratory_block, 0, 3);
		StructureUtils.setBlock(world, x + 7, y + 1, z + 7, Blocks.CHEST, 2, 3);
		StructureUtils.setBlock(world, x + 7, y + 1, z + 6, Blocks.AIR, 0, 3);
		StructureUtils.setBlock(world, x + 7, y + 1, z + 5, Blocks.AIR, 0, 3);
		StructureUtils.setBlock(world, x + 7, y + 1, z + 4, Blocks.AIR, 0, 3);
		StructureUtils.setBlock(world, x + 7, y + 1, z + 3, Blocks.AIR, 0, 3);
		StructureUtils.setBlock(world, x + 7, y + 1, z + 2, Blocks.AIR, 0, 3);
		StructureUtils.setBlock(world, x + 7, y + 1, z + 1, Blocks.AIR, 0, 3);
		StructureUtils.setBlock(world, x + 7, y + 1, z + 0, ModBlocks.laboratory_block, 0, 3);
		StructureUtils.setBlock(world, x + 8, y + 1, z + 8, ModBlocks.laboratory_block, 0, 3);
		StructureUtils.setBlock(world, x + 8, y + 1, z + 7, Blocks.CHEST, 2, 3);
		StructureUtils.setBlock(world, x + 8, y + 1, z + 6, Blocks.AIR, 0, 3);
		StructureUtils.setBlock(world, x + 8, y + 1, z + 5, ModBlocks.fertilization_machine, 1, 3);
		StructureUtils.setBlock(world, x + 8, y + 1, z + 4, Blocks.AIR, 0, 3);
		StructureUtils.setBlock(world, x + 8, y + 1, z + 3, ModBlocks.tissue_analyzer, 1, 3);
		StructureUtils.setBlock(world, x + 8, y + 1, z + 2, Blocks.AIR, 0, 3);
		StructureUtils.setBlock(world, x + 8, y + 1, z + 0, ModBlocks.laboratory_block, 0, 3);
		StructureUtils.setBlock(world, x + 9, y + 1, z + 8, ModBlocks.laboratory_block, 0, 3);
		StructureUtils.setBlock(world, x + 9, y + 1, z + 7, ModBlocks.laboratory_block, 0, 3);
		StructureUtils.setBlock(world, x + 9, y + 1, z + 6, ModBlocks.laboratory_block, 0, 3);
		StructureUtils.setBlock(world, x + 9, y + 1, z + 5, ModBlocks.laboratory_block, 0, 3);
		StructureUtils.setBlock(world, x + 9, y + 1, z + 4, ModBlocks.laboratory_block, 0, 3);
		StructureUtils.setBlock(world, x + 9, y + 1, z + 3, ModBlocks.laboratory_block, 0, 3);
		StructureUtils.setBlock(world, x + 9, y + 1, z + 2, ModBlocks.laboratory_block, 0, 3);
		StructureUtils.setBlock(world, x + 9, y + 1, z + 1, ModBlocks.laboratory_block, 0, 3);
		StructureUtils.setBlock(world, x + 9, y + 1, z + 0, ModBlocks.laboratory_block, 0, 3);
		StructureUtils.setBlock(world, x + 0, y + 2, z + 6, ModBlocks.laboratory_block, 0, 3);
		StructureUtils.setBlock(world, x + 0, y + 2, z + 5, ModBlocks.laboratory_block, 0, 3);
		StructureUtils.setBlock(world, x + 0, y + 2, z + 4, ModBlocks.laboratory_light_panel, 0, 3);
		StructureUtils.setBlock(world, x + 0, y + 2, z + 3, ModBlocks.laboratory_block, 0, 3);
		StructureUtils.setBlock(world, x + 0, y + 2, z + 2, ModBlocks.laboratory_block, 0, 3);
		StructureUtils.setBlock(world, x + 1, y + 2, z + 6, ModBlocks.laboratory_block, 0, 3);
		StructureUtils.setBlock(world, x + 1, y + 2, z + 5, Blocks.AIR, 0, 3);
		StructureUtils.setBlock(world, x + 1, y + 2, z + 4, Blocks.AIR, 0, 3);
		StructureUtils.setBlock(world, x + 1, y + 2, z + 3, Blocks.AIR, 0, 3);
		StructureUtils.setBlock(world, x + 1, y + 2, z + 2, ModBlocks.laboratory_block, 0, 3);
		StructureUtils.setBlock(world, x + 2, y + 2, z + 6, ModBlocks.laboratory_light_panel, 0, 3);
		StructureUtils.setBlock(world, x + 2, y + 2, z + 5, Blocks.AIR, 0, 3);
		StructureUtils.setBlock(world, x + 2, y + 2, z + 4, Blocks.AIR, 0, 3);
		StructureUtils.setBlock(world, x + 2, y + 2, z + 3, Blocks.AIR, 0, 3);
		StructureUtils.setBlock(world, x + 2, y + 2, z + 2, ModBlocks.laboratory_light_panel, 0, 3);
		StructureUtils.setBlock(world, x + 3, y + 2, z + 6, ModBlocks.laboratory_block, 0, 3);
		StructureUtils.setBlock(world, x + 3, y + 2, z + 5, Blocks.AIR, 0, 3);
		StructureUtils.setBlock(world, x + 3, y + 2, z + 4, Blocks.AIR, 0, 3);
		StructureUtils.setBlock(world, x + 3, y + 2, z + 3, Blocks.AIR, 0, 3);
		StructureUtils.setBlock(world, x + 3, y + 2, z + 2, ModBlocks.laboratory_block, 0, 3);
		StructureUtils.setBlock(world, x + 4, y + 2, z + 8, ModBlocks.laboratory_block, 0, 3);
		StructureUtils.setBlock(world, x + 4, y + 2, z + 7, ModBlocks.laboratory_block, 0, 3);
		StructureUtils.setBlock(world, x + 4, y + 2, z + 6, ModBlocks.laboratory_block, 0, 3);
		StructureUtils.setBlock(world, x + 4, y + 2, z + 5, Blocks.GLASS, 0, 3);
		StructureUtils.setBlock(world, x + 4, y + 2, z + 4, Blocks.GLASS, 0, 3);
		StructureUtils.setBlock(world, x + 4, y + 2, z + 3, Blocks.GLASS, 0, 3);
		StructureUtils.setBlock(world, x + 4, y + 2, z + 2, ModBlocks.laboratory_block, 0, 3);
		StructureUtils.setBlock(world, x + 4, y + 2, z + 1, ModBlocks.laboratory_block, 0, 3);
		StructureUtils.setBlock(world, x + 4, y + 2, z + 0, ModBlocks.laboratory_block, 0, 3);
		StructureUtils.setBlock(world, x + 5, y + 2, z + 8, ModBlocks.laboratory_block, 0, 3);
		StructureUtils.setBlock(world, x + 5, y + 2, z + 7, Blocks.AIR, 0, 3);
		StructureUtils.setBlock(world, x + 5, y + 2, z + 6, Blocks.AIR, 0, 3);
		StructureUtils.setBlock(world, x + 5, y + 2, z + 5, Blocks.AIR, 0, 3);
		StructureUtils.setBlock(world, x + 5, y + 2, z + 4, Blocks.AIR, 0, 3);
		StructureUtils.setBlock(world, x + 5, y + 2, z + 3, Blocks.AIR, 0, 3);
		StructureUtils.setBlock(world, x + 5, y + 2, z + 2, Blocks.AIR, 0, 3);
		StructureUtils.setBlock(world, x + 5, y + 2, z + 1, Blocks.AIR, 0, 3);
		StructureUtils.setBlock(world, x + 5, y + 2, z + 0, ModBlocks.laboratory_block, 0, 3);
		StructureUtils.setBlock(world, x + 6, y + 2, z + 8, ModBlocks.laboratory_block, 0, 3);
		StructureUtils.setBlock(world, x + 6, y + 2, z + 7, Blocks.AIR, 0, 3);
		StructureUtils.setBlock(world, x + 6, y + 2, z + 6, Blocks.AIR, 0, 3);
		StructureUtils.setBlock(world, x + 6, y + 2, z + 5, Blocks.AIR, 0, 3);
		StructureUtils.setBlock(world, x + 6, y + 2, z + 4, Blocks.AIR, 0, 3);
		StructureUtils.setBlock(world, x + 6, y + 2, z + 3, Blocks.AIR, 0, 3);
		StructureUtils.setBlock(world, x + 6, y + 2, z + 2, Blocks.AIR, 0, 3);
		StructureUtils.setBlock(world, x + 6, y + 2, z + 1, Blocks.AIR, 0, 3);
		StructureUtils.setBlock(world, x + 6, y + 2, z + 0, ModBlocks.laboratory_block, 0, 3);
		StructureUtils.setBlock(world, x + 7, y + 2, z + 8, ModBlocks.laboratory_block, 0, 3);
		StructureUtils.setBlock(world, x + 7, y + 2, z + 7, Blocks.AIR, 0, 3);
		StructureUtils.setBlock(world, x + 7, y + 2, z + 6, Blocks.AIR, 0, 3);
		StructureUtils.setBlock(world, x + 7, y + 2, z + 5, Blocks.AIR, 0, 3);
		StructureUtils.setBlock(world, x + 7, y + 2, z + 4, Blocks.AIR, 0, 3);
		StructureUtils.setBlock(world, x + 7, y + 2, z + 3, Blocks.AIR, 0, 3);
		StructureUtils.setBlock(world, x + 7, y + 2, z + 2, Blocks.AIR, 0, 3);
		StructureUtils.setBlock(world, x + 7, y + 2, z + 1, Blocks.AIR, 0, 3);
		StructureUtils.setBlock(world, x + 7, y + 2, z + 0, ModBlocks.laboratory_block, 0, 3);
		StructureUtils.setBlock(world, x + 8, y + 2, z + 8, ModBlocks.laboratory_block, 0, 3);
		StructureUtils.setBlock(world, x + 8, y + 2, z + 7, Blocks.AIR, 0, 3);
		StructureUtils.setBlock(world, x + 8, y + 2, z + 6, Blocks.AIR, 0, 3);
		StructureUtils.setBlock(world, x + 8, y + 2, z + 5, Blocks.AIR, 0, 3);
		StructureUtils.setBlock(world, x + 8, y + 2, z + 4, Blocks.AIR, 0, 3);
		StructureUtils.setBlock(world, x + 8, y + 2, z + 3, Blocks.AIR, 0, 3);
		StructureUtils.setBlock(world, x + 8, y + 2, z + 2, Blocks.AIR, 0, 3);
		StructureUtils.setBlock(world, x + 8, y + 2, z + 0, ModBlocks.laboratory_block, 0, 3);
		StructureUtils.setBlock(world, x + 9, y + 2, z + 8, ModBlocks.laboratory_block, 0, 3);
		StructureUtils.setBlock(world, x + 9, y + 2, z + 7, ModBlocks.laboratory_block, 0, 3);
		StructureUtils.setBlock(world, x + 9, y + 2, z + 6, ModBlocks.laboratory_block, 0, 3);
		StructureUtils.setBlock(world, x + 9, y + 2, z + 5, ModBlocks.laboratory_block, 0, 3);
		StructureUtils.setBlock(world, x + 9, y + 2, z + 4, ModBlocks.laboratory_block, 0, 3);
		StructureUtils.setBlock(world, x + 9, y + 2, z + 3, ModBlocks.laboratory_block, 0, 3);
		StructureUtils.setBlock(world, x + 9, y + 2, z + 2, ModBlocks.laboratory_block, 0, 3);
		StructureUtils.setBlock(world, x + 9, y + 2, z + 1, ModBlocks.laboratory_block, 0, 3);
		StructureUtils.setBlock(world, x + 9, y + 2, z + 0, ModBlocks.laboratory_block, 0, 3);
		StructureUtils.setBlock(world, x + 0, y + 3, z + 6, ModBlocks.laboratory_block, 0, 3);
		StructureUtils.setBlock(world, x + 0, y + 3, z + 5, ModBlocks.laboratory_block, 0, 3);
		StructureUtils.setBlock(world, x + 0, y + 3, z + 4, ModBlocks.laboratory_block, 0, 3);
		StructureUtils.setBlock(world, x + 0, y + 3, z + 3, ModBlocks.laboratory_block, 0, 3);
		StructureUtils.setBlock(world, x + 0, y + 3, z + 2, ModBlocks.laboratory_block, 0, 3);
		StructureUtils.setBlock(world, x + 1, y + 3, z + 6, ModBlocks.laboratory_block, 0, 3);
		StructureUtils.setBlock(world, x + 1, y + 3, z + 5, Blocks.AIR, 0, 3);
		StructureUtils.setBlock(world, x + 1, y + 3, z + 4, Blocks.AIR, 0, 3);
		StructureUtils.setBlock(world, x + 1, y + 3, z + 3, Blocks.AIR, 0, 3);
		StructureUtils.setBlock(world, x + 1, y + 3, z + 2, ModBlocks.laboratory_block, 0, 3);
		StructureUtils.setBlock(world, x + 2, y + 3, z + 6, ModBlocks.laboratory_block, 0, 3);
		StructureUtils.setBlock(world, x + 2, y + 3, z + 5, Blocks.AIR, 0, 3);
		StructureUtils.setBlock(world, x + 2, y + 3, z + 4, Blocks.AIR, 0, 3);
		StructureUtils.setBlock(world, x + 2, y + 3, z + 3, Blocks.AIR, 0, 3);
		StructureUtils.setBlock(world, x + 2, y + 3, z + 2, ModBlocks.laboratory_block, 0, 3);
		StructureUtils.setBlock(world, x + 3, y + 3, z + 6, ModBlocks.laboratory_block, 0, 3);
		StructureUtils.setBlock(world, x + 3, y + 3, z + 5, Blocks.AIR, 0, 3);
		StructureUtils.setBlock(world, x + 3, y + 3, z + 4, Blocks.AIR, 0, 3);
		StructureUtils.setBlock(world, x + 3, y + 3, z + 3, Blocks.AIR, 0, 3);
		StructureUtils.setBlock(world, x + 3, y + 3, z + 2, ModBlocks.laboratory_block, 0, 3);
		StructureUtils.setBlock(world, x + 4, y + 3, z + 8, ModBlocks.laboratory_block, 0, 3);
		StructureUtils.setBlock(world, x + 4, y + 3, z + 7, ModBlocks.laboratory_block, 0, 3);
		StructureUtils.setBlock(world, x + 4, y + 3, z + 6, ModBlocks.laboratory_block, 0, 3);
		StructureUtils.setBlock(world, x + 4, y + 3, z + 5, Blocks.GLASS, 0, 3);
		StructureUtils.setBlock(world, x + 4, y + 3, z + 4, Blocks.GLASS, 0, 3);
		StructureUtils.setBlock(world, x + 4, y + 3, z + 3, Blocks.GLASS, 0, 3);
		StructureUtils.setBlock(world, x + 4, y + 3, z + 2, ModBlocks.laboratory_block, 0, 3);
		StructureUtils.setBlock(world, x + 4, y + 3, z + 1, ModBlocks.laboratory_block, 0, 3);
		StructureUtils.setBlock(world, x + 4, y + 3, z + 0, ModBlocks.laboratory_block, 0, 3);
		StructureUtils.setBlock(world, x + 5, y + 3, z + 8, ModBlocks.laboratory_block, 0, 3);
		StructureUtils.setBlock(world, x + 5, y + 3, z + 7, Blocks.AIR, 0, 3);
		StructureUtils.setBlock(world, x + 5, y + 3, z + 6, Blocks.AIR, 0, 3);
		StructureUtils.setBlock(world, x + 5, y + 3, z + 5, Blocks.AIR, 0, 3);
		StructureUtils.setBlock(world, x + 5, y + 3, z + 4, Blocks.AIR, 0, 3);
		StructureUtils.setBlock(world, x + 5, y + 3, z + 3, Blocks.AIR, 0, 3);
		StructureUtils.setBlock(world, x + 5, y + 3, z + 2, Blocks.AIR, 0, 3);
		StructureUtils.setBlock(world, x + 5, y + 3, z + 1, Blocks.AIR, 0, 3);
		StructureUtils.setBlock(world, x + 5, y + 3, z + 0, ModBlocks.laboratory_block, 0, 3);
		StructureUtils.setBlock(world, x + 6, y + 3, z + 8, ModBlocks.laboratory_block, 0, 3);
		StructureUtils.setBlock(world, x + 6, y + 3, z + 7, Blocks.AIR, 0, 3);
		StructureUtils.setBlock(world, x + 6, y + 3, z + 6, Blocks.AIR, 0, 3);
		StructureUtils.setBlock(world, x + 6, y + 3, z + 5, Blocks.AIR, 0, 3);
		StructureUtils.setBlock(world, x + 6, y + 3, z + 4, Blocks.AIR, 0, 3);
		StructureUtils.setBlock(world, x + 6, y + 3, z + 3, Blocks.AIR, 0, 3);
		StructureUtils.setBlock(world, x + 6, y + 3, z + 2, Blocks.AIR, 0, 3);
		StructureUtils.setBlock(world, x + 6, y + 3, z + 1, Blocks.AIR, 0, 3);
		StructureUtils.setBlock(world, x + 6, y + 3, z + 0, ModBlocks.laboratory_block, 0, 3);
		StructureUtils.setBlock(world, x + 7, y + 3, z + 8, ModBlocks.laboratory_block, 0, 3);
		StructureUtils.setBlock(world, x + 7, y + 3, z + 7, Blocks.AIR, 0, 3);
		StructureUtils.setBlock(world, x + 7, y + 3, z + 6, Blocks.AIR, 0, 3);
		StructureUtils.setBlock(world, x + 7, y + 3, z + 5, Blocks.AIR, 0, 3);
		StructureUtils.setBlock(world, x + 7, y + 3, z + 4, Blocks.AIR, 0, 3);
		StructureUtils.setBlock(world, x + 7, y + 3, z + 3, Blocks.AIR, 0, 3);
		StructureUtils.setBlock(world, x + 7, y + 3, z + 2, Blocks.AIR, 0, 3);
		StructureUtils.setBlock(world, x + 7, y + 3, z + 1, Blocks.AIR, 0, 3);
		StructureUtils.setBlock(world, x + 7, y + 3, z + 0, ModBlocks.laboratory_block, 0, 3);
		StructureUtils.setBlock(world, x + 8, y + 3, z + 8, ModBlocks.laboratory_block, 0, 3);
		StructureUtils.setBlock(world, x + 8, y + 3, z + 7, Blocks.AIR, 0, 3);
		StructureUtils.setBlock(world, x + 8, y + 3, z + 6, Blocks.AIR, 0, 3);
		StructureUtils.setBlock(world, x + 8, y + 3, z + 5, Blocks.AIR, 0, 3);
		StructureUtils.setBlock(world, x + 8, y + 3, z + 4, Blocks.AIR, 0, 3);
		StructureUtils.setBlock(world, x + 8, y + 3, z + 3, Blocks.AIR, 0, 3);
		StructureUtils.setBlock(world, x + 8, y + 3, z + 2, Blocks.AIR, 0, 3);
		StructureUtils.setBlock(world, x + 8, y + 3, z + 0, ModBlocks.laboratory_block, 0, 3);
		StructureUtils.setBlock(world, x + 9, y + 3, z + 8, ModBlocks.laboratory_block, 0, 3);
		StructureUtils.setBlock(world, x + 9, y + 3, z + 7, ModBlocks.laboratory_block, 0, 3);
		StructureUtils.setBlock(world, x + 9, y + 3, z + 6, ModBlocks.laboratory_block, 0, 3);
		StructureUtils.setBlock(world, x + 9, y + 3, z + 5, ModBlocks.laboratory_block, 0, 3);
		StructureUtils.setBlock(world, x + 9, y + 3, z + 4, ModBlocks.laboratory_block, 0, 3);
		StructureUtils.setBlock(world, x + 9, y + 3, z + 3, ModBlocks.laboratory_block, 0, 3);
		StructureUtils.setBlock(world, x + 9, y + 3, z + 2, ModBlocks.laboratory_block, 0, 3);
		StructureUtils.setBlock(world, x + 9, y + 3, z + 1, ModBlocks.laboratory_block, 0, 3);
		StructureUtils.setBlock(world, x + 9, y + 3, z + 0, ModBlocks.laboratory_block, 0, 3);
		StructureUtils.setBlock(world, x + 0, y + 4, z + 6, ModBlocks.laboratory_block, 0, 3);
		StructureUtils.setBlock(world, x + 0, y + 4, z + 5, ModBlocks.laboratory_block, 0, 3);
		StructureUtils.setBlock(world, x + 0, y + 4, z + 4, ModBlocks.laboratory_block, 0, 3);
		StructureUtils.setBlock(world, x + 0, y + 4, z + 3, ModBlocks.laboratory_block, 0, 3);
		StructureUtils.setBlock(world, x + 0, y + 4, z + 2, ModBlocks.laboratory_block, 0, 3);
		StructureUtils.setBlock(world, x + 1, y + 4, z + 6, ModBlocks.laboratory_block, 0, 3);
		StructureUtils.setBlock(world, x + 1, y + 4, z + 5, ModBlocks.laboratory_block, 0, 3);
		StructureUtils.setBlock(world, x + 1, y + 4, z + 4, ModBlocks.laboratory_block, 0, 3);
		StructureUtils.setBlock(world, x + 1, y + 4, z + 3, ModBlocks.laboratory_block, 0, 3);
		StructureUtils.setBlock(world, x + 1, y + 4, z + 2, ModBlocks.laboratory_block, 0, 3);
		StructureUtils.setBlock(world, x + 2, y + 4, z + 6, ModBlocks.laboratory_block, 0, 3);
		StructureUtils.setBlock(world, x + 2, y + 4, z + 5, ModBlocks.laboratory_block, 0, 3);
		StructureUtils.setBlock(world, x + 2, y + 4, z + 4, ModBlocks.laboratory_block, 0, 3);
		StructureUtils.setBlock(world, x + 2, y + 4, z + 3, ModBlocks.laboratory_block, 0, 3);
		StructureUtils.setBlock(world, x + 2, y + 4, z + 2, ModBlocks.laboratory_block, 0, 3);
		StructureUtils.setBlock(world, x + 3, y + 4, z + 6, ModBlocks.laboratory_block, 0, 3);
		StructureUtils.setBlock(world, x + 3, y + 4, z + 5, ModBlocks.laboratory_block, 0, 3);
		StructureUtils.setBlock(world, x + 3, y + 4, z + 4, ModBlocks.laboratory_block, 0, 3);
		StructureUtils.setBlock(world, x + 3, y + 4, z + 3, ModBlocks.laboratory_block, 0, 3);
		StructureUtils.setBlock(world, x + 3, y + 4, z + 2, ModBlocks.laboratory_block, 0, 3);
		StructureUtils.setBlock(world, x + 4, y + 4, z + 8, ModBlocks.laboratory_block, 0, 3);
		StructureUtils.setBlock(world, x + 4, y + 4, z + 7, ModBlocks.laboratory_block, 0, 3);
		StructureUtils.setBlock(world, x + 4, y + 4, z + 6, ModBlocks.laboratory_block, 0, 3);
		StructureUtils.setBlock(world, x + 4, y + 4, z + 5, ModBlocks.laboratory_block, 0, 3);
		StructureUtils.setBlock(world, x + 4, y + 4, z + 4, ModBlocks.laboratory_block, 0, 3);
		StructureUtils.setBlock(world, x + 4, y + 4, z + 3, ModBlocks.laboratory_block, 0, 3);
		StructureUtils.setBlock(world, x + 4, y + 4, z + 2, ModBlocks.laboratory_block, 0, 3);
		StructureUtils.setBlock(world, x + 4, y + 4, z + 1, ModBlocks.laboratory_block, 0, 3);
		StructureUtils.setBlock(world, x + 4, y + 4, z + 0, ModBlocks.laboratory_block, 0, 3);
		StructureUtils.setBlock(world, x + 5, y + 4, z + 8, ModBlocks.laboratory_block, 0, 3);
		StructureUtils.setBlock(world, x + 5, y + 4, z + 7, ModBlocks.laboratory_block, 0, 3);
		StructureUtils.setBlock(world, x + 5, y + 4, z + 6, ModBlocks.laboratory_block, 0, 3);
		StructureUtils.setBlock(world, x + 5, y + 4, z + 5, ModBlocks.laboratory_block, 0, 3);
		StructureUtils.setBlock(world, x + 5, y + 4, z + 4, ModBlocks.laboratory_block, 0, 3);
		StructureUtils.setBlock(world, x + 5, y + 4, z + 3, ModBlocks.laboratory_block, 0, 3);
		StructureUtils.setBlock(world, x + 5, y + 4, z + 2, ModBlocks.laboratory_block, 0, 3);
		StructureUtils.setBlock(world, x + 5, y + 4, z + 1, ModBlocks.laboratory_block, 0, 3);
		StructureUtils.setBlock(world, x + 5, y + 4, z + 0, ModBlocks.laboratory_block, 0, 3);
		StructureUtils.setBlock(world, x + 6, y + 4, z + 8, ModBlocks.laboratory_block, 0, 3);
		StructureUtils.setBlock(world, x + 6, y + 4, z + 7, ModBlocks.laboratory_block, 0, 3);
		StructureUtils.setBlock(world, x + 6, y + 4, z + 6, ModBlocks.laboratory_block, 0, 3);
		StructureUtils.setBlock(world, x + 6, y + 4, z + 5, ModBlocks.laboratory_block, 0, 3);
		StructureUtils.setBlock(world, x + 6, y + 4, z + 4, ModBlocks.laboratory_block, 0, 3);
		StructureUtils.setBlock(world, x + 6, y + 4, z + 3, ModBlocks.laboratory_block, 0, 3);
		StructureUtils.setBlock(world, x + 6, y + 4, z + 2, ModBlocks.laboratory_block, 0, 3);
		StructureUtils.setBlock(world, x + 6, y + 4, z + 1, ModBlocks.laboratory_block, 0, 3);
		StructureUtils.setBlock(world, x + 6, y + 4, z + 0, ModBlocks.laboratory_block, 0, 3);
		StructureUtils.setBlock(world, x + 7, y + 4, z + 8, ModBlocks.laboratory_block, 0, 3);
		StructureUtils.setBlock(world, x + 7, y + 4, z + 7, ModBlocks.laboratory_block, 0, 3);
		StructureUtils.setBlock(world, x + 7, y + 4, z + 6, ModBlocks.laboratory_light_panel, 0, 3);
		StructureUtils.setBlock(world, x + 7, y + 4, z + 5, ModBlocks.laboratory_block, 0, 3);
		StructureUtils.setBlock(world, x + 7, y + 4, z + 4, ModBlocks.laboratory_block, 0, 3);
		StructureUtils.setBlock(world, x + 7, y + 4, z + 3, ModBlocks.laboratory_block, 0, 3);
		StructureUtils.setBlock(world, x + 7, y + 4, z + 2, ModBlocks.laboratory_light_panel, 0, 3);
		StructureUtils.setBlock(world, x + 7, y + 4, z + 1, ModBlocks.laboratory_block, 0, 3);
		StructureUtils.setBlock(world, x + 7, y + 4, z + 0, ModBlocks.laboratory_block, 0, 3);
		StructureUtils.setBlock(world, x + 8, y + 4, z + 8, ModBlocks.laboratory_block, 0, 3);
		StructureUtils.setBlock(world, x + 8, y + 4, z + 7, ModBlocks.laboratory_block, 0, 3);
		StructureUtils.setBlock(world, x + 8, y + 4, z + 6, ModBlocks.laboratory_block, 0, 3);
		StructureUtils.setBlock(world, x + 8, y + 4, z + 5, ModBlocks.laboratory_block, 0, 3);
		StructureUtils.setBlock(world, x + 8, y + 4, z + 4, ModBlocks.laboratory_block, 0, 3);
		StructureUtils.setBlock(world, x + 8, y + 4, z + 3, ModBlocks.laboratory_block, 0, 3);
		StructureUtils.setBlock(world, x + 8, y + 4, z + 2, ModBlocks.laboratory_block, 0, 3);
		StructureUtils.setBlock(world, x + 8, y + 4, z + 0, ModBlocks.laboratory_block, 0, 3);
		StructureUtils.setBlock(world, x + 9, y + 4, z + 8, ModBlocks.laboratory_block, 0, 3);
		StructureUtils.setBlock(world, x + 9, y + 4, z + 7, ModBlocks.laboratory_block, 0, 3);
		StructureUtils.setBlock(world, x + 9, y + 4, z + 6, ModBlocks.laboratory_block, 0, 3);
		StructureUtils.setBlock(world, x + 9, y + 4, z + 5, ModBlocks.laboratory_block, 0, 3);
		StructureUtils.setBlock(world, x + 9, y + 4, z + 4, ModBlocks.laboratory_block, 0, 3);
		StructureUtils.setBlock(world, x + 9, y + 4, z + 3, ModBlocks.laboratory_block, 0, 3);
		StructureUtils.setBlock(world, x + 9, y + 4, z + 2, ModBlocks.laboratory_block, 0, 3);
		StructureUtils.setBlock(world, x + 9, y + 4, z + 1, ModBlocks.laboratory_block, 0, 3);
		StructureUtils.setBlock(world, x + 9, y + 4, z + 0, ModBlocks.laboratory_block, 0, 3);
		StructureUtils.setBlock(world, x + 6, y + 5, z + 1, ModBlocks.laboratory_block, 0, 3);
		StructureUtils.setBlock(world, x + 7, y + 5, z + 2, ModBlocks.laboratory_block, 0, 3);
		StructureUtils.setBlock(world, x + 7, y + 5, z + 0, ModBlocks.laboratory_block, 0, 3);
		StructureUtils.setBlock(world, x + 8, y + 5, z + 2, ModBlocks.laboratory_block, 0, 3);
		StructureUtils.setBlock(world, x + 8, y + 5, z + 0, ModBlocks.laboratory_block, 0, 3);
		StructureUtils.setBlock(world, x + 9, y + 5, z + 1, ModBlocks.laboratory_block, 0, 3);
		StructureUtils.setBlock(world, x + 0, y + 6, z + 6, Blocks.GRASS, 0, 3);
		StructureUtils.setBlock(world, x + 0, y + 6, z + 5, Blocks.GRASS, 0, 3);
		StructureUtils.setBlock(world, x + 0, y + 6, z + 4, Blocks.GRASS, 0, 3);
		StructureUtils.setBlock(world, x + 0, y + 6, z + 3, Blocks.GRASS, 0, 3);
		StructureUtils.setBlock(world, x + 0, y + 6, z + 2, Blocks.GRASS, 0, 3);
		StructureUtils.setBlock(world, x + 0, y + 6, z + 1, Blocks.GRASS, 0, 3);
		StructureUtils.setBlock(world, x + 0, y + 6, z + 0, Blocks.GRASS, 0, 3);
		StructureUtils.setBlock(world, x + 1, y + 6, z + 6, Blocks.GRASS, 0, 3);
		StructureUtils.setBlock(world, x + 1, y + 6, z + 5, Blocks.GRASS, 0, 3);
		StructureUtils.setBlock(world, x + 1, y + 6, z + 4, Blocks.GRASS, 0, 3);
		StructureUtils.setBlock(world, x + 1, y + 6, z + 3, Blocks.GRASS, 0, 3);
		StructureUtils.setBlock(world, x + 1, y + 6, z + 2, Blocks.GRASS, 0, 3);
		StructureUtils.setBlock(world, x + 1, y + 6, z + 1, Blocks.GRASS, 0, 3);
		StructureUtils.setBlock(world, x + 1, y + 6, z + 0, Blocks.GRASS, 0, 3);
		StructureUtils.setBlock(world, x + 2, y + 6, z + 6, Blocks.GRASS, 0, 3);
		StructureUtils.setBlock(world, x + 2, y + 6, z + 5, Blocks.GRASS, 0, 3);
		StructureUtils.setBlock(world, x + 2, y + 6, z + 4, Blocks.GRASS, 0, 3);
		StructureUtils.setBlock(world, x + 2, y + 6, z + 3, Blocks.GRASS, 0, 3);
		StructureUtils.setBlock(world, x + 2, y + 6, z + 2, Blocks.GRASS, 0, 3);
		StructureUtils.setBlock(world, x + 2, y + 6, z + 1, Blocks.GRASS, 0, 3);
		StructureUtils.setBlock(world, x + 2, y + 6, z + 0, Blocks.GRASS, 0, 3);
		StructureUtils.setBlock(world, x + 3, y + 6, z + 6, Blocks.GRASS, 0, 3);
		StructureUtils.setBlock(world, x + 3, y + 6, z + 5, Blocks.GRASS, 0, 3);
		StructureUtils.setBlock(world, x + 3, y + 6, z + 4, Blocks.GRASS, 0, 3);
		StructureUtils.setBlock(world, x + 3, y + 6, z + 3, Blocks.GRASS, 0, 3);
		StructureUtils.setBlock(world, x + 3, y + 6, z + 2, Blocks.COBBLESTONE, 0, 3);
		StructureUtils.setBlock(world, x + 3, y + 6, z + 1, Blocks.GRASS, 0, 3);
		StructureUtils.setBlock(world, x + 3, y + 6, z + 0, Blocks.GRASS, 0, 3);
		StructureUtils.setBlock(world, x + 4, y + 6, z + 8, Blocks.COBBLESTONE, 0, 3);
		StructureUtils.setBlock(world, x + 4, y + 6, z + 7, Blocks.COBBLESTONE, 0, 3);
		StructureUtils.setBlock(world, x + 4, y + 6, z + 6, Blocks.COBBLESTONE, 0, 3);
		StructureUtils.setBlock(world, x + 4, y + 6, z + 5, Blocks.COBBLESTONE, 0, 3);
		StructureUtils.setBlock(world, x + 4, y + 6, z + 4, Blocks.COBBLESTONE, 0, 3);
		StructureUtils.setBlock(world, x + 4, y + 6, z + 3, Blocks.COBBLESTONE, 0, 3);
		StructureUtils.setBlock(world, x + 4, y + 6, z + 2, Blocks.COBBLESTONE, 0, 3);
		StructureUtils.setBlock(world, x + 4, y + 6, z + 1, Blocks.COBBLESTONE, 0, 3);
		StructureUtils.setBlock(world, x + 4, y + 6, z + 0, Blocks.COBBLESTONE, 0, 3);
		StructureUtils.setBlock(world, x + 5, y + 6, z + 8, Blocks.COBBLESTONE, 0, 3);
		StructureUtils.setBlock(world, x + 5, y + 6, z + 7, Blocks.PLANKS, 0, 3);
		StructureUtils.setBlock(world, x + 5, y + 6, z + 6, Blocks.PLANKS, 0, 3);
		StructureUtils.setBlock(world, x + 5, y + 6, z + 5, Blocks.PLANKS, 0, 3);
		StructureUtils.setBlock(world, x + 5, y + 6, z + 4, Blocks.PLANKS, 0, 3);
		StructureUtils.setBlock(world, x + 5, y + 6, z + 3, Blocks.PLANKS, 0, 3);
		StructureUtils.setBlock(world, x + 5, y + 6, z + 2, Blocks.PLANKS, 0, 3);
		StructureUtils.setBlock(world, x + 5, y + 6, z + 1, Blocks.PLANKS, 0, 3);
		StructureUtils.setBlock(world, x + 5, y + 6, z + 0, Blocks.COBBLESTONE, 0, 3);
		StructureUtils.setBlock(world, x + 6, y + 6, z + 8, Blocks.COBBLESTONE, 0, 3);
